2025-07-17 10:58:21,742 INFO: Hypercon startup [in C:\projects\hypercon\app\__init__.py:66]
2025-07-17 16:40:30,068 INFO: Hypercon startup [in C:\projects\hypercon\app\__init__.py:66]
2025-07-17 16:40:40,138 INFO: Hypercon startup [in C:\projects\hypercon\app\__init__.py:66]
2025-07-17 16:40:45,035 ERROR: Unhandled Exception [in C:\projects\hypercon\app\__init__.py:111]
Traceback (most recent call last):
  File "C:\projects\hypercon\.venv\Lib\site-packages\flask\app.py", line 1484, in full_dispatch_request
    rv = self.dispatch_request()
         ^^^^^^^^^^^^^^^^^^^^^^^
  File "C:\projects\hypercon\.venv\Lib\site-packages\flask\app.py", line 1458, in dispatch_request
    self.raise_routing_exception(req)
  File "C:\projects\hypercon\.venv\Lib\site-packages\flask\app.py", line 1440, in raise_routing_exception
    raise request.routing_exception  # type: ignore
    ^^^^^^^^^^^^^^^^^^^^^^^^^^^^^^^
  File "C:\projects\hypercon\.venv\Lib\site-packages\flask\ctx.py", line 353, in match_request
    result = self.url_adapter.match(return_rule=True)  # type: ignore
             ^^^^^^^^^^^^^^^^^^^^^^^^^^^^^^^^^^^^^^^^
  File "C:\projects\hypercon\.venv\Lib\site-packages\werkzeug\routing\map.py", line 629, in match
    raise NotFound() from None
werkzeug.exceptions.NotFound: 404 Not Found: The requested URL was not found on the server. If you entered the URL manually please check your spelling and try again.
2025-07-17 16:40:45,081 ERROR: Exception on /cgi-bin/luci/;stok=/locale [GET] [in C:\projects\hypercon\.venv\Lib\site-packages\flask\app.py:1414]
Traceback (most recent call last):
  File "C:\projects\hypercon\.venv\Lib\site-packages\flask\app.py", line 2190, in wsgi_app
    response = self.full_dispatch_request()
               ^^^^^^^^^^^^^^^^^^^^^^^^^^^^
  File "C:\projects\hypercon\.venv\Lib\site-packages\flask\app.py", line 1486, in full_dispatch_request
    rv = self.handle_user_exception(e)
         ^^^^^^^^^^^^^^^^^^^^^^^^^^^^^
  File "C:\projects\hypercon\.venv\Lib\site-packages\flask\app.py", line 1341, in handle_user_exception
    return self.handle_http_exception(e)
           ^^^^^^^^^^^^^^^^^^^^^^^^^^^^^
  File "C:\projects\hypercon\.venv\Lib\site-packages\flask\app.py", line 1281, in handle_http_exception
    return self.ensure_sync(handler)(e)
           ^^^^^^^^^^^^^^^^^^^^^^^^^^^^
  File "C:\projects\hypercon\.venv\Lib\site-packages\flask\app.py", line 1484, in full_dispatch_request
    rv = self.dispatch_request()
         ^^^^^^^^^^^^^^^^^^^^^^^
  File "C:\projects\hypercon\.venv\Lib\site-packages\flask\app.py", line 1458, in dispatch_request
    self.raise_routing_exception(req)
  File "C:\projects\hypercon\.venv\Lib\site-packages\flask\app.py", line 1440, in raise_routing_exception
    raise request.routing_exception  # type: ignore
    ^^^^^^^^^^^^^^^^^^^^^^^^^^^^^^^
  File "C:\projects\hypercon\.venv\Lib\site-packages\flask\ctx.py", line 353, in match_request
    result = self.url_adapter.match(return_rule=True)  # type: ignore
             ^^^^^^^^^^^^^^^^^^^^^^^^^^^^^^^^^^^^^^^^
  File "C:\projects\hypercon\.venv\Lib\site-packages\werkzeug\routing\map.py", line 629, in match
    raise NotFound() from None
werkzeug.exceptions.NotFound: 404 Not Found: The requested URL was not found on the server. If you entered the URL manually please check your spelling and try again.
2025-07-17 16:40:45,083 ERROR: Unhandled Exception [in C:\projects\hypercon\app\__init__.py:111]
werkzeug.exceptions.InternalServerError: 500 Internal Server Error: The server encountered an internal error and was unable to complete your request. Either the server is overloaded or there is an error in the application.
2025-07-17 16:41:38,068 ERROR: Unhandled Exception [in C:\projects\hypercon\app\__init__.py:111]
Traceback (most recent call last):
  File "C:\projects\hypercon\.venv\Lib\site-packages\flask\app.py", line 1484, in full_dispatch_request
    rv = self.dispatch_request()
         ^^^^^^^^^^^^^^^^^^^^^^^
  File "C:\projects\hypercon\.venv\Lib\site-packages\flask\app.py", line 1458, in dispatch_request
    self.raise_routing_exception(req)
  File "C:\projects\hypercon\.venv\Lib\site-packages\flask\app.py", line 1440, in raise_routing_exception
    raise request.routing_exception  # type: ignore
    ^^^^^^^^^^^^^^^^^^^^^^^^^^^^^^^
  File "C:\projects\hypercon\.venv\Lib\site-packages\flask\ctx.py", line 353, in match_request
    result = self.url_adapter.match(return_rule=True)  # type: ignore
             ^^^^^^^^^^^^^^^^^^^^^^^^^^^^^^^^^^^^^^^^
  File "C:\projects\hypercon\.venv\Lib\site-packages\werkzeug\routing\map.py", line 629, in match
    raise NotFound() from None
werkzeug.exceptions.NotFound: 404 Not Found: The requested URL was not found on the server. If you entered the URL manually please check your spelling and try again.
2025-07-17 16:41:38,070 ERROR: Exception on /geoserver [GET] [in C:\projects\hypercon\.venv\Lib\site-packages\flask\app.py:1414]
Traceback (most recent call last):
  File "C:\projects\hypercon\.venv\Lib\site-packages\flask\app.py", line 2190, in wsgi_app
    response = self.full_dispatch_request()
               ^^^^^^^^^^^^^^^^^^^^^^^^^^^^
  File "C:\projects\hypercon\.venv\Lib\site-packages\flask\app.py", line 1486, in full_dispatch_request
    rv = self.handle_user_exception(e)
         ^^^^^^^^^^^^^^^^^^^^^^^^^^^^^
  File "C:\projects\hypercon\.venv\Lib\site-packages\flask\app.py", line 1341, in handle_user_exception
    return self.handle_http_exception(e)
           ^^^^^^^^^^^^^^^^^^^^^^^^^^^^^
  File "C:\projects\hypercon\.venv\Lib\site-packages\flask\app.py", line 1281, in handle_http_exception
    return self.ensure_sync(handler)(e)
           ^^^^^^^^^^^^^^^^^^^^^^^^^^^^
  File "C:\projects\hypercon\.venv\Lib\site-packages\flask\app.py", line 1484, in full_dispatch_request
    rv = self.dispatch_request()
         ^^^^^^^^^^^^^^^^^^^^^^^
  File "C:\projects\hypercon\.venv\Lib\site-packages\flask\app.py", line 1458, in dispatch_request
    self.raise_routing_exception(req)
  File "C:\projects\hypercon\.venv\Lib\site-packages\flask\app.py", line 1440, in raise_routing_exception
    raise request.routing_exception  # type: ignore
    ^^^^^^^^^^^^^^^^^^^^^^^^^^^^^^^
  File "C:\projects\hypercon\.venv\Lib\site-packages\flask\ctx.py", line 353, in match_request
    result = self.url_adapter.match(return_rule=True)  # type: ignore
             ^^^^^^^^^^^^^^^^^^^^^^^^^^^^^^^^^^^^^^^^
  File "C:\projects\hypercon\.venv\Lib\site-packages\werkzeug\routing\map.py", line 629, in match
    raise NotFound() from None
werkzeug.exceptions.NotFound: 404 Not Found: The requested URL was not found on the server. If you entered the URL manually please check your spelling and try again.
2025-07-17 16:41:38,071 ERROR: Unhandled Exception [in C:\projects\hypercon\app\__init__.py:111]
werkzeug.exceptions.InternalServerError: 500 Internal Server Error: The server encountered an internal error and was unable to complete your request. Either the server is overloaded or there is an error in the application.
2025-07-17 16:42:52,333 ERROR: Unhandled Exception [in C:\projects\hypercon\app\__init__.py:111]
Traceback (most recent call last):
  File "C:\projects\hypercon\.venv\Lib\site-packages\flask\app.py", line 1484, in full_dispatch_request
    rv = self.dispatch_request()
         ^^^^^^^^^^^^^^^^^^^^^^^
  File "C:\projects\hypercon\.venv\Lib\site-packages\flask\app.py", line 1458, in dispatch_request
    self.raise_routing_exception(req)
  File "C:\projects\hypercon\.venv\Lib\site-packages\flask\app.py", line 1440, in raise_routing_exception
    raise request.routing_exception  # type: ignore
    ^^^^^^^^^^^^^^^^^^^^^^^^^^^^^^^
  File "C:\projects\hypercon\.venv\Lib\site-packages\flask\ctx.py", line 353, in match_request
    result = self.url_adapter.match(return_rule=True)  # type: ignore
             ^^^^^^^^^^^^^^^^^^^^^^^^^^^^^^^^^^^^^^^^
  File "C:\projects\hypercon\.venv\Lib\site-packages\werkzeug\routing\map.py", line 629, in match
    raise NotFound() from None
werkzeug.exceptions.NotFound: 404 Not Found: The requested URL was not found on the server. If you entered the URL manually please check your spelling and try again.
2025-07-17 16:42:52,339 ERROR: Exception on /cgi-bin/luci/;stok=/locale [GET] [in C:\projects\hypercon\.venv\Lib\site-packages\flask\app.py:1414]
Traceback (most recent call last):
  File "C:\projects\hypercon\.venv\Lib\site-packages\flask\app.py", line 2190, in wsgi_app
    response = self.full_dispatch_request()
               ^^^^^^^^^^^^^^^^^^^^^^^^^^^^
  File "C:\projects\hypercon\.venv\Lib\site-packages\flask\app.py", line 1486, in full_dispatch_request
    rv = self.handle_user_exception(e)
         ^^^^^^^^^^^^^^^^^^^^^^^^^^^^^
  File "C:\projects\hypercon\.venv\Lib\site-packages\flask\app.py", line 1341, in handle_user_exception
    return self.handle_http_exception(e)
           ^^^^^^^^^^^^^^^^^^^^^^^^^^^^^
  File "C:\projects\hypercon\.venv\Lib\site-packages\flask\app.py", line 1281, in handle_http_exception
    return self.ensure_sync(handler)(e)
           ^^^^^^^^^^^^^^^^^^^^^^^^^^^^
  File "C:\projects\hypercon\.venv\Lib\site-packages\flask\app.py", line 1484, in full_dispatch_request
    rv = self.dispatch_request()
         ^^^^^^^^^^^^^^^^^^^^^^^
  File "C:\projects\hypercon\.venv\Lib\site-packages\flask\app.py", line 1458, in dispatch_request
    self.raise_routing_exception(req)
  File "C:\projects\hypercon\.venv\Lib\site-packages\flask\app.py", line 1440, in raise_routing_exception
    raise request.routing_exception  # type: ignore
    ^^^^^^^^^^^^^^^^^^^^^^^^^^^^^^^
  File "C:\projects\hypercon\.venv\Lib\site-packages\flask\ctx.py", line 353, in match_request
    result = self.url_adapter.match(return_rule=True)  # type: ignore
             ^^^^^^^^^^^^^^^^^^^^^^^^^^^^^^^^^^^^^^^^
  File "C:\projects\hypercon\.venv\Lib\site-packages\werkzeug\routing\map.py", line 629, in match
    raise NotFound() from None
werkzeug.exceptions.NotFound: 404 Not Found: The requested URL was not found on the server. If you entered the URL manually please check your spelling and try again.
2025-07-17 16:42:52,346 ERROR: Unhandled Exception [in C:\projects\hypercon\app\__init__.py:111]
werkzeug.exceptions.InternalServerError: 500 Internal Server Error: The server encountered an internal error and was unable to complete your request. Either the server is overloaded or there is an error in the application.
2025-07-17 16:43:40,385 ERROR: Unhandled Exception [in C:\projects\hypercon\app\__init__.py:111]
Traceback (most recent call last):
  File "C:\projects\hypercon\.venv\Lib\site-packages\flask\app.py", line 1484, in full_dispatch_request
    rv = self.dispatch_request()
         ^^^^^^^^^^^^^^^^^^^^^^^
  File "C:\projects\hypercon\.venv\Lib\site-packages\flask\app.py", line 1458, in dispatch_request
    self.raise_routing_exception(req)
  File "C:\projects\hypercon\.venv\Lib\site-packages\flask\app.py", line 1440, in raise_routing_exception
    raise request.routing_exception  # type: ignore
    ^^^^^^^^^^^^^^^^^^^^^^^^^^^^^^^
  File "C:\projects\hypercon\.venv\Lib\site-packages\flask\ctx.py", line 353, in match_request
    result = self.url_adapter.match(return_rule=True)  # type: ignore
             ^^^^^^^^^^^^^^^^^^^^^^^^^^^^^^^^^^^^^^^^
  File "C:\projects\hypercon\.venv\Lib\site-packages\werkzeug\routing\map.py", line 629, in match
    raise NotFound() from None
werkzeug.exceptions.NotFound: 404 Not Found: The requested URL was not found on the server. If you entered the URL manually please check your spelling and try again.
2025-07-17 16:43:40,387 ERROR: Exception on /cgi-bin/luci/;stok=/locale [GET] [in C:\projects\hypercon\.venv\Lib\site-packages\flask\app.py:1414]
Traceback (most recent call last):
  File "C:\projects\hypercon\.venv\Lib\site-packages\flask\app.py", line 2190, in wsgi_app
    response = self.full_dispatch_request()
               ^^^^^^^^^^^^^^^^^^^^^^^^^^^^
  File "C:\projects\hypercon\.venv\Lib\site-packages\flask\app.py", line 1486, in full_dispatch_request
    rv = self.handle_user_exception(e)
         ^^^^^^^^^^^^^^^^^^^^^^^^^^^^^
  File "C:\projects\hypercon\.venv\Lib\site-packages\flask\app.py", line 1341, in handle_user_exception
    return self.handle_http_exception(e)
           ^^^^^^^^^^^^^^^^^^^^^^^^^^^^^
  File "C:\projects\hypercon\.venv\Lib\site-packages\flask\app.py", line 1281, in handle_http_exception
    return self.ensure_sync(handler)(e)
           ^^^^^^^^^^^^^^^^^^^^^^^^^^^^
  File "C:\projects\hypercon\.venv\Lib\site-packages\flask\app.py", line 1484, in full_dispatch_request
    rv = self.dispatch_request()
         ^^^^^^^^^^^^^^^^^^^^^^^
  File "C:\projects\hypercon\.venv\Lib\site-packages\flask\app.py", line 1458, in dispatch_request
    self.raise_routing_exception(req)
  File "C:\projects\hypercon\.venv\Lib\site-packages\flask\app.py", line 1440, in raise_routing_exception
    raise request.routing_exception  # type: ignore
    ^^^^^^^^^^^^^^^^^^^^^^^^^^^^^^^
  File "C:\projects\hypercon\.venv\Lib\site-packages\flask\ctx.py", line 353, in match_request
    result = self.url_adapter.match(return_rule=True)  # type: ignore
             ^^^^^^^^^^^^^^^^^^^^^^^^^^^^^^^^^^^^^^^^
  File "C:\projects\hypercon\.venv\Lib\site-packages\werkzeug\routing\map.py", line 629, in match
    raise NotFound() from None
werkzeug.exceptions.NotFound: 404 Not Found: The requested URL was not found on the server. If you entered the URL manually please check your spelling and try again.
2025-07-17 16:43:40,389 ERROR: Unhandled Exception [in C:\projects\hypercon\app\__init__.py:111]
werkzeug.exceptions.InternalServerError: 500 Internal Server Error: The server encountered an internal error and was unable to complete your request. Either the server is overloaded or there is an error in the application.
2025-07-17 16:44:30,207 INFO: Hypercon startup [in C:\projects\hypercon\app\__init__.py:66]
2025-07-17 16:44:44,816 ERROR: Unhandled Exception [in C:\projects\hypercon\app\__init__.py:111]
Traceback (most recent call last):
  File "C:\projects\hypercon\.venv\Lib\site-packages\flask\app.py", line 1484, in full_dispatch_request
    rv = self.dispatch_request()
         ^^^^^^^^^^^^^^^^^^^^^^^
  File "C:\projects\hypercon\.venv\Lib\site-packages\flask\app.py", line 1458, in dispatch_request
    self.raise_routing_exception(req)
  File "C:\projects\hypercon\.venv\Lib\site-packages\flask\app.py", line 1440, in raise_routing_exception
    raise request.routing_exception  # type: ignore
    ^^^^^^^^^^^^^^^^^^^^^^^^^^^^^^^
  File "C:\projects\hypercon\.venv\Lib\site-packages\flask\ctx.py", line 353, in match_request
    result = self.url_adapter.match(return_rule=True)  # type: ignore
             ^^^^^^^^^^^^^^^^^^^^^^^^^^^^^^^^^^^^^^^^
  File "C:\projects\hypercon\.venv\Lib\site-packages\werkzeug\routing\map.py", line 629, in match
    raise NotFound() from None
werkzeug.exceptions.NotFound: 404 Not Found: The requested URL was not found on the server. If you entered the URL manually please check your spelling and try again.
2025-07-17 16:44:44,834 ERROR: Exception on /favicon.ico [GET] [in C:\projects\hypercon\.venv\Lib\site-packages\flask\app.py:1414]
Traceback (most recent call last):
  File "C:\projects\hypercon\.venv\Lib\site-packages\flask\app.py", line 2190, in wsgi_app
    response = self.full_dispatch_request()
               ^^^^^^^^^^^^^^^^^^^^^^^^^^^^
  File "C:\projects\hypercon\.venv\Lib\site-packages\flask\app.py", line 1486, in full_dispatch_request
    rv = self.handle_user_exception(e)
         ^^^^^^^^^^^^^^^^^^^^^^^^^^^^^
  File "C:\projects\hypercon\.venv\Lib\site-packages\flask\app.py", line 1341, in handle_user_exception
    return self.handle_http_exception(e)
           ^^^^^^^^^^^^^^^^^^^^^^^^^^^^^
  File "C:\projects\hypercon\.venv\Lib\site-packages\flask\app.py", line 1281, in handle_http_exception
    return self.ensure_sync(handler)(e)
           ^^^^^^^^^^^^^^^^^^^^^^^^^^^^
  File "C:\projects\hypercon\.venv\Lib\site-packages\flask\app.py", line 1484, in full_dispatch_request
    rv = self.dispatch_request()
         ^^^^^^^^^^^^^^^^^^^^^^^
  File "C:\projects\hypercon\.venv\Lib\site-packages\flask\app.py", line 1458, in dispatch_request
    self.raise_routing_exception(req)
  File "C:\projects\hypercon\.venv\Lib\site-packages\flask\app.py", line 1440, in raise_routing_exception
    raise request.routing_exception  # type: ignore
    ^^^^^^^^^^^^^^^^^^^^^^^^^^^^^^^
  File "C:\projects\hypercon\.venv\Lib\site-packages\flask\ctx.py", line 353, in match_request
    result = self.url_adapter.match(return_rule=True)  # type: ignore
             ^^^^^^^^^^^^^^^^^^^^^^^^^^^^^^^^^^^^^^^^
  File "C:\projects\hypercon\.venv\Lib\site-packages\werkzeug\routing\map.py", line 629, in match
    raise NotFound() from None
werkzeug.exceptions.NotFound: 404 Not Found: The requested URL was not found on the server. If you entered the URL manually please check your spelling and try again.
2025-07-17 16:44:44,836 ERROR: Unhandled Exception [in C:\projects\hypercon\app\__init__.py:111]
werkzeug.exceptions.InternalServerError: 500 Internal Server Error: The server encountered an internal error and was unable to complete your request. Either the server is overloaded or there is an error in the application.
2025-07-17 16:44:55,663 ERROR: Unhandled Exception [in C:\projects\hypercon\app\__init__.py:111]
Traceback (most recent call last):
  File "C:\projects\hypercon\.venv\Lib\site-packages\flask\app.py", line 1484, in full_dispatch_request
    rv = self.dispatch_request()
         ^^^^^^^^^^^^^^^^^^^^^^^
  File "C:\projects\hypercon\.venv\Lib\site-packages\flask\app.py", line 1458, in dispatch_request
    self.raise_routing_exception(req)
  File "C:\projects\hypercon\.venv\Lib\site-packages\flask\app.py", line 1440, in raise_routing_exception
    raise request.routing_exception  # type: ignore
    ^^^^^^^^^^^^^^^^^^^^^^^^^^^^^^^
  File "C:\projects\hypercon\.venv\Lib\site-packages\flask\ctx.py", line 353, in match_request
    result = self.url_adapter.match(return_rule=True)  # type: ignore
             ^^^^^^^^^^^^^^^^^^^^^^^^^^^^^^^^^^^^^^^^
  File "C:\projects\hypercon\.venv\Lib\site-packages\werkzeug\routing\map.py", line 629, in match
    raise NotFound() from None
werkzeug.exceptions.NotFound: 404 Not Found: The requested URL was not found on the server. If you entered the URL manually please check your spelling and try again.
2025-07-17 16:44:55,665 ERROR: Exception on /favicon.ico [GET] [in C:\projects\hypercon\.venv\Lib\site-packages\flask\app.py:1414]
Traceback (most recent call last):
  File "C:\projects\hypercon\.venv\Lib\site-packages\flask\app.py", line 2190, in wsgi_app
    response = self.full_dispatch_request()
               ^^^^^^^^^^^^^^^^^^^^^^^^^^^^
  File "C:\projects\hypercon\.venv\Lib\site-packages\flask\app.py", line 1486, in full_dispatch_request
    rv = self.handle_user_exception(e)
         ^^^^^^^^^^^^^^^^^^^^^^^^^^^^^
  File "C:\projects\hypercon\.venv\Lib\site-packages\flask\app.py", line 1341, in handle_user_exception
    return self.handle_http_exception(e)
           ^^^^^^^^^^^^^^^^^^^^^^^^^^^^^
  File "C:\projects\hypercon\.venv\Lib\site-packages\flask\app.py", line 1281, in handle_http_exception
    return self.ensure_sync(handler)(e)
           ^^^^^^^^^^^^^^^^^^^^^^^^^^^^
  File "C:\projects\hypercon\.venv\Lib\site-packages\flask\app.py", line 1484, in full_dispatch_request
    rv = self.dispatch_request()
         ^^^^^^^^^^^^^^^^^^^^^^^
  File "C:\projects\hypercon\.venv\Lib\site-packages\flask\app.py", line 1458, in dispatch_request
    self.raise_routing_exception(req)
  File "C:\projects\hypercon\.venv\Lib\site-packages\flask\app.py", line 1440, in raise_routing_exception
    raise request.routing_exception  # type: ignore
    ^^^^^^^^^^^^^^^^^^^^^^^^^^^^^^^
  File "C:\projects\hypercon\.venv\Lib\site-packages\flask\ctx.py", line 353, in match_request
    result = self.url_adapter.match(return_rule=True)  # type: ignore
             ^^^^^^^^^^^^^^^^^^^^^^^^^^^^^^^^^^^^^^^^
  File "C:\projects\hypercon\.venv\Lib\site-packages\werkzeug\routing\map.py", line 629, in match
    raise NotFound() from None
werkzeug.exceptions.NotFound: 404 Not Found: The requested URL was not found on the server. If you entered the URL manually please check your spelling and try again.
2025-07-17 16:44:55,667 ERROR: Unhandled Exception [in C:\projects\hypercon\app\__init__.py:111]
werkzeug.exceptions.InternalServerError: 500 Internal Server Error: The server encountered an internal error and was unable to complete your request. Either the server is overloaded or there is an error in the application.
2025-07-17 16:44:57,730 ERROR: Unhandled Exception [in C:\projects\hypercon\app\__init__.py:111]
Traceback (most recent call last):
  File "C:\projects\hypercon\.venv\Lib\site-packages\flask\app.py", line 1484, in full_dispatch_request
    rv = self.dispatch_request()
         ^^^^^^^^^^^^^^^^^^^^^^^
  File "C:\projects\hypercon\.venv\Lib\site-packages\flask\app.py", line 1458, in dispatch_request
    self.raise_routing_exception(req)
  File "C:\projects\hypercon\.venv\Lib\site-packages\flask\app.py", line 1440, in raise_routing_exception
    raise request.routing_exception  # type: ignore
    ^^^^^^^^^^^^^^^^^^^^^^^^^^^^^^^
  File "C:\projects\hypercon\.venv\Lib\site-packages\flask\ctx.py", line 353, in match_request
    result = self.url_adapter.match(return_rule=True)  # type: ignore
             ^^^^^^^^^^^^^^^^^^^^^^^^^^^^^^^^^^^^^^^^
  File "C:\projects\hypercon\.venv\Lib\site-packages\werkzeug\routing\map.py", line 629, in match
    raise NotFound() from None
werkzeug.exceptions.NotFound: 404 Not Found: The requested URL was not found on the server. If you entered the URL manually please check your spelling and try again.
2025-07-17 16:44:57,732 ERROR: Exception on /favicon.ico [GET] [in C:\projects\hypercon\.venv\Lib\site-packages\flask\app.py:1414]
Traceback (most recent call last):
  File "C:\projects\hypercon\.venv\Lib\site-packages\flask\app.py", line 2190, in wsgi_app
    response = self.full_dispatch_request()
               ^^^^^^^^^^^^^^^^^^^^^^^^^^^^
  File "C:\projects\hypercon\.venv\Lib\site-packages\flask\app.py", line 1486, in full_dispatch_request
    rv = self.handle_user_exception(e)
         ^^^^^^^^^^^^^^^^^^^^^^^^^^^^^
  File "C:\projects\hypercon\.venv\Lib\site-packages\flask\app.py", line 1341, in handle_user_exception
    return self.handle_http_exception(e)
           ^^^^^^^^^^^^^^^^^^^^^^^^^^^^^
  File "C:\projects\hypercon\.venv\Lib\site-packages\flask\app.py", line 1281, in handle_http_exception
    return self.ensure_sync(handler)(e)
           ^^^^^^^^^^^^^^^^^^^^^^^^^^^^
  File "C:\projects\hypercon\.venv\Lib\site-packages\flask\app.py", line 1484, in full_dispatch_request
    rv = self.dispatch_request()
         ^^^^^^^^^^^^^^^^^^^^^^^
  File "C:\projects\hypercon\.venv\Lib\site-packages\flask\app.py", line 1458, in dispatch_request
    self.raise_routing_exception(req)
  File "C:\projects\hypercon\.venv\Lib\site-packages\flask\app.py", line 1440, in raise_routing_exception
    raise request.routing_exception  # type: ignore
    ^^^^^^^^^^^^^^^^^^^^^^^^^^^^^^^
  File "C:\projects\hypercon\.venv\Lib\site-packages\flask\ctx.py", line 353, in match_request
    result = self.url_adapter.match(return_rule=True)  # type: ignore
             ^^^^^^^^^^^^^^^^^^^^^^^^^^^^^^^^^^^^^^^^
  File "C:\projects\hypercon\.venv\Lib\site-packages\werkzeug\routing\map.py", line 629, in match
    raise NotFound() from None
werkzeug.exceptions.NotFound: 404 Not Found: The requested URL was not found on the server. If you entered the URL manually please check your spelling and try again.
2025-07-17 16:44:57,734 ERROR: Unhandled Exception [in C:\projects\hypercon\app\__init__.py:111]
werkzeug.exceptions.InternalServerError: 500 Internal Server Error: The server encountered an internal error and was unable to complete your request. Either the server is overloaded or there is an error in the application.
2025-07-17 16:45:31,410 ERROR: Unhandled Exception [in C:\projects\hypercon\app\__init__.py:111]
Traceback (most recent call last):
  File "C:\projects\hypercon\.venv\Lib\site-packages\flask\app.py", line 1484, in full_dispatch_request
    rv = self.dispatch_request()
         ^^^^^^^^^^^^^^^^^^^^^^^
  File "C:\projects\hypercon\.venv\Lib\site-packages\flask\app.py", line 1458, in dispatch_request
    self.raise_routing_exception(req)
  File "C:\projects\hypercon\.venv\Lib\site-packages\flask\app.py", line 1440, in raise_routing_exception
    raise request.routing_exception  # type: ignore
    ^^^^^^^^^^^^^^^^^^^^^^^^^^^^^^^
  File "C:\projects\hypercon\.venv\Lib\site-packages\flask\ctx.py", line 353, in match_request
    result = self.url_adapter.match(return_rule=True)  # type: ignore
             ^^^^^^^^^^^^^^^^^^^^^^^^^^^^^^^^^^^^^^^^
  File "C:\projects\hypercon\.venv\Lib\site-packages\werkzeug\routing\map.py", line 629, in match
    raise NotFound() from None
werkzeug.exceptions.NotFound: 404 Not Found: The requested URL was not found on the server. If you entered the URL manually please check your spelling and try again.
2025-07-17 16:45:31,416 ERROR: Exception on /cgi-bin/luci/;stok=/locale [GET] [in C:\projects\hypercon\.venv\Lib\site-packages\flask\app.py:1414]
Traceback (most recent call last):
  File "C:\projects\hypercon\.venv\Lib\site-packages\flask\app.py", line 2190, in wsgi_app
    response = self.full_dispatch_request()
               ^^^^^^^^^^^^^^^^^^^^^^^^^^^^
  File "C:\projects\hypercon\.venv\Lib\site-packages\flask\app.py", line 1486, in full_dispatch_request
    rv = self.handle_user_exception(e)
         ^^^^^^^^^^^^^^^^^^^^^^^^^^^^^
  File "C:\projects\hypercon\.venv\Lib\site-packages\flask\app.py", line 1341, in handle_user_exception
    return self.handle_http_exception(e)
           ^^^^^^^^^^^^^^^^^^^^^^^^^^^^^
  File "C:\projects\hypercon\.venv\Lib\site-packages\flask\app.py", line 1281, in handle_http_exception
    return self.ensure_sync(handler)(e)
           ^^^^^^^^^^^^^^^^^^^^^^^^^^^^
  File "C:\projects\hypercon\.venv\Lib\site-packages\flask\app.py", line 1484, in full_dispatch_request
    rv = self.dispatch_request()
         ^^^^^^^^^^^^^^^^^^^^^^^
  File "C:\projects\hypercon\.venv\Lib\site-packages\flask\app.py", line 1458, in dispatch_request
    self.raise_routing_exception(req)
  File "C:\projects\hypercon\.venv\Lib\site-packages\flask\app.py", line 1440, in raise_routing_exception
    raise request.routing_exception  # type: ignore
    ^^^^^^^^^^^^^^^^^^^^^^^^^^^^^^^
  File "C:\projects\hypercon\.venv\Lib\site-packages\flask\ctx.py", line 353, in match_request
    result = self.url_adapter.match(return_rule=True)  # type: ignore
             ^^^^^^^^^^^^^^^^^^^^^^^^^^^^^^^^^^^^^^^^
  File "C:\projects\hypercon\.venv\Lib\site-packages\werkzeug\routing\map.py", line 629, in match
    raise NotFound() from None
werkzeug.exceptions.NotFound: 404 Not Found: The requested URL was not found on the server. If you entered the URL manually please check your spelling and try again.
2025-07-17 16:45:31,422 ERROR: Unhandled Exception [in C:\projects\hypercon\app\__init__.py:111]
werkzeug.exceptions.InternalServerError: 500 Internal Server Error: The server encountered an internal error and was unable to complete your request. Either the server is overloaded or there is an error in the application.
2025-07-17 16:46:23,071 ERROR: Unhandled Exception [in C:\projects\hypercon\app\__init__.py:111]
Traceback (most recent call last):
  File "C:\projects\hypercon\.venv\Lib\site-packages\flask\app.py", line 1484, in full_dispatch_request
    rv = self.dispatch_request()
         ^^^^^^^^^^^^^^^^^^^^^^^
  File "C:\projects\hypercon\.venv\Lib\site-packages\flask\app.py", line 1458, in dispatch_request
    self.raise_routing_exception(req)
  File "C:\projects\hypercon\.venv\Lib\site-packages\flask\app.py", line 1440, in raise_routing_exception
    raise request.routing_exception  # type: ignore
    ^^^^^^^^^^^^^^^^^^^^^^^^^^^^^^^
  File "C:\projects\hypercon\.venv\Lib\site-packages\flask\ctx.py", line 353, in match_request
    result = self.url_adapter.match(return_rule=True)  # type: ignore
             ^^^^^^^^^^^^^^^^^^^^^^^^^^^^^^^^^^^^^^^^
  File "C:\projects\hypercon\.venv\Lib\site-packages\werkzeug\routing\map.py", line 629, in match
    raise NotFound() from None
werkzeug.exceptions.NotFound: 404 Not Found: The requested URL was not found on the server. If you entered the URL manually please check your spelling and try again.
2025-07-17 16:46:23,073 ERROR: Exception on /cgi-bin/luci/;stok=/locale [GET] [in C:\projects\hypercon\.venv\Lib\site-packages\flask\app.py:1414]
Traceback (most recent call last):
  File "C:\projects\hypercon\.venv\Lib\site-packages\flask\app.py", line 2190, in wsgi_app
    response = self.full_dispatch_request()
               ^^^^^^^^^^^^^^^^^^^^^^^^^^^^
  File "C:\projects\hypercon\.venv\Lib\site-packages\flask\app.py", line 1486, in full_dispatch_request
    rv = self.handle_user_exception(e)
         ^^^^^^^^^^^^^^^^^^^^^^^^^^^^^
  File "C:\projects\hypercon\.venv\Lib\site-packages\flask\app.py", line 1341, in handle_user_exception
    return self.handle_http_exception(e)
           ^^^^^^^^^^^^^^^^^^^^^^^^^^^^^
  File "C:\projects\hypercon\.venv\Lib\site-packages\flask\app.py", line 1281, in handle_http_exception
    return self.ensure_sync(handler)(e)
           ^^^^^^^^^^^^^^^^^^^^^^^^^^^^
  File "C:\projects\hypercon\.venv\Lib\site-packages\flask\app.py", line 1484, in full_dispatch_request
    rv = self.dispatch_request()
         ^^^^^^^^^^^^^^^^^^^^^^^
  File "C:\projects\hypercon\.venv\Lib\site-packages\flask\app.py", line 1458, in dispatch_request
    self.raise_routing_exception(req)
  File "C:\projects\hypercon\.venv\Lib\site-packages\flask\app.py", line 1440, in raise_routing_exception
    raise request.routing_exception  # type: ignore
    ^^^^^^^^^^^^^^^^^^^^^^^^^^^^^^^
  File "C:\projects\hypercon\.venv\Lib\site-packages\flask\ctx.py", line 353, in match_request
    result = self.url_adapter.match(return_rule=True)  # type: ignore
             ^^^^^^^^^^^^^^^^^^^^^^^^^^^^^^^^^^^^^^^^
  File "C:\projects\hypercon\.venv\Lib\site-packages\werkzeug\routing\map.py", line 629, in match
    raise NotFound() from None
werkzeug.exceptions.NotFound: 404 Not Found: The requested URL was not found on the server. If you entered the URL manually please check your spelling and try again.
2025-07-17 16:46:23,074 ERROR: Unhandled Exception [in C:\projects\hypercon\app\__init__.py:111]
werkzeug.exceptions.InternalServerError: 500 Internal Server Error: The server encountered an internal error and was unable to complete your request. Either the server is overloaded or there is an error in the application.
2025-07-17 16:47:47,540 INFO: Hypercon startup [in C:\projects\hypercon\app\__init__.py:66]
2025-07-17 16:47:50,893 ERROR: Unhandled Exception [in C:\projects\hypercon\app\__init__.py:111]
Traceback (most recent call last):
  File "C:\projects\hypercon\.venv\Lib\site-packages\flask\app.py", line 1484, in full_dispatch_request
    rv = self.dispatch_request()
         ^^^^^^^^^^^^^^^^^^^^^^^
  File "C:\projects\hypercon\.venv\Lib\site-packages\flask\app.py", line 1458, in dispatch_request
    self.raise_routing_exception(req)
  File "C:\projects\hypercon\.venv\Lib\site-packages\flask\app.py", line 1440, in raise_routing_exception
    raise request.routing_exception  # type: ignore
    ^^^^^^^^^^^^^^^^^^^^^^^^^^^^^^^
  File "C:\projects\hypercon\.venv\Lib\site-packages\flask\ctx.py", line 353, in match_request
    result = self.url_adapter.match(return_rule=True)  # type: ignore
             ^^^^^^^^^^^^^^^^^^^^^^^^^^^^^^^^^^^^^^^^
  File "C:\projects\hypercon\.venv\Lib\site-packages\werkzeug\routing\map.py", line 629, in match
    raise NotFound() from None
werkzeug.exceptions.NotFound: 404 Not Found: The requested URL was not found on the server. If you entered the URL manually please check your spelling and try again.
2025-07-17 16:47:50,899 ERROR: Exception on /favicon.ico [GET] [in C:\projects\hypercon\.venv\Lib\site-packages\flask\app.py:1414]
Traceback (most recent call last):
  File "C:\projects\hypercon\.venv\Lib\site-packages\flask\app.py", line 2190, in wsgi_app
    response = self.full_dispatch_request()
               ^^^^^^^^^^^^^^^^^^^^^^^^^^^^
  File "C:\projects\hypercon\.venv\Lib\site-packages\flask\app.py", line 1486, in full_dispatch_request
    rv = self.handle_user_exception(e)
         ^^^^^^^^^^^^^^^^^^^^^^^^^^^^^
  File "C:\projects\hypercon\.venv\Lib\site-packages\flask\app.py", line 1341, in handle_user_exception
    return self.handle_http_exception(e)
           ^^^^^^^^^^^^^^^^^^^^^^^^^^^^^
  File "C:\projects\hypercon\.venv\Lib\site-packages\flask\app.py", line 1281, in handle_http_exception
    return self.ensure_sync(handler)(e)
           ^^^^^^^^^^^^^^^^^^^^^^^^^^^^
  File "C:\projects\hypercon\.venv\Lib\site-packages\flask\app.py", line 1484, in full_dispatch_request
    rv = self.dispatch_request()
         ^^^^^^^^^^^^^^^^^^^^^^^
  File "C:\projects\hypercon\.venv\Lib\site-packages\flask\app.py", line 1458, in dispatch_request
    self.raise_routing_exception(req)
  File "C:\projects\hypercon\.venv\Lib\site-packages\flask\app.py", line 1440, in raise_routing_exception
    raise request.routing_exception  # type: ignore
    ^^^^^^^^^^^^^^^^^^^^^^^^^^^^^^^
  File "C:\projects\hypercon\.venv\Lib\site-packages\flask\ctx.py", line 353, in match_request
    result = self.url_adapter.match(return_rule=True)  # type: ignore
             ^^^^^^^^^^^^^^^^^^^^^^^^^^^^^^^^^^^^^^^^
  File "C:\projects\hypercon\.venv\Lib\site-packages\werkzeug\routing\map.py", line 629, in match
    raise NotFound() from None
werkzeug.exceptions.NotFound: 404 Not Found: The requested URL was not found on the server. If you entered the URL manually please check your spelling and try again.
2025-07-17 16:47:50,902 ERROR: Unhandled Exception [in C:\projects\hypercon\app\__init__.py:111]
werkzeug.exceptions.InternalServerError: 500 Internal Server Error: The server encountered an internal error and was unable to complete your request. Either the server is overloaded or there is an error in the application.
2025-07-17 16:48:14,711 ERROR: Unhandled Exception [in C:\projects\hypercon\app\__init__.py:111]
Traceback (most recent call last):
  File "C:\projects\hypercon\.venv\Lib\site-packages\flask\app.py", line 1484, in full_dispatch_request
    rv = self.dispatch_request()
         ^^^^^^^^^^^^^^^^^^^^^^^
  File "C:\projects\hypercon\.venv\Lib\site-packages\flask\app.py", line 1458, in dispatch_request
    self.raise_routing_exception(req)
  File "C:\projects\hypercon\.venv\Lib\site-packages\flask\app.py", line 1440, in raise_routing_exception
    raise request.routing_exception  # type: ignore
    ^^^^^^^^^^^^^^^^^^^^^^^^^^^^^^^
  File "C:\projects\hypercon\.venv\Lib\site-packages\flask\ctx.py", line 353, in match_request
    result = self.url_adapter.match(return_rule=True)  # type: ignore
             ^^^^^^^^^^^^^^^^^^^^^^^^^^^^^^^^^^^^^^^^
  File "C:\projects\hypercon\.venv\Lib\site-packages\werkzeug\routing\map.py", line 629, in match
    raise NotFound() from None
werkzeug.exceptions.NotFound: 404 Not Found: The requested URL was not found on the server. If you entered the URL manually please check your spelling and try again.
2025-07-17 16:48:14,713 ERROR: Exception on /favicon.ico [GET] [in C:\projects\hypercon\.venv\Lib\site-packages\flask\app.py:1414]
Traceback (most recent call last):
  File "C:\projects\hypercon\.venv\Lib\site-packages\flask\app.py", line 2190, in wsgi_app
    response = self.full_dispatch_request()
               ^^^^^^^^^^^^^^^^^^^^^^^^^^^^
  File "C:\projects\hypercon\.venv\Lib\site-packages\flask\app.py", line 1486, in full_dispatch_request
    rv = self.handle_user_exception(e)
         ^^^^^^^^^^^^^^^^^^^^^^^^^^^^^
  File "C:\projects\hypercon\.venv\Lib\site-packages\flask\app.py", line 1341, in handle_user_exception
    return self.handle_http_exception(e)
           ^^^^^^^^^^^^^^^^^^^^^^^^^^^^^
  File "C:\projects\hypercon\.venv\Lib\site-packages\flask\app.py", line 1281, in handle_http_exception
    return self.ensure_sync(handler)(e)
           ^^^^^^^^^^^^^^^^^^^^^^^^^^^^
  File "C:\projects\hypercon\.venv\Lib\site-packages\flask\app.py", line 1484, in full_dispatch_request
    rv = self.dispatch_request()
         ^^^^^^^^^^^^^^^^^^^^^^^
  File "C:\projects\hypercon\.venv\Lib\site-packages\flask\app.py", line 1458, in dispatch_request
    self.raise_routing_exception(req)
  File "C:\projects\hypercon\.venv\Lib\site-packages\flask\app.py", line 1440, in raise_routing_exception
    raise request.routing_exception  # type: ignore
    ^^^^^^^^^^^^^^^^^^^^^^^^^^^^^^^
  File "C:\projects\hypercon\.venv\Lib\site-packages\flask\ctx.py", line 353, in match_request
    result = self.url_adapter.match(return_rule=True)  # type: ignore
             ^^^^^^^^^^^^^^^^^^^^^^^^^^^^^^^^^^^^^^^^
  File "C:\projects\hypercon\.venv\Lib\site-packages\werkzeug\routing\map.py", line 629, in match
    raise NotFound() from None
werkzeug.exceptions.NotFound: 404 Not Found: The requested URL was not found on the server. If you entered the URL manually please check your spelling and try again.
2025-07-17 16:48:14,715 ERROR: Unhandled Exception [in C:\projects\hypercon\app\__init__.py:111]
werkzeug.exceptions.InternalServerError: 500 Internal Server Error: The server encountered an internal error and was unable to complete your request. Either the server is overloaded or there is an error in the application.
2025-07-17 16:48:27,107 ERROR: Unhandled Exception [in C:\projects\hypercon\app\__init__.py:111]
Traceback (most recent call last):
  File "C:\projects\hypercon\.venv\Lib\site-packages\flask\app.py", line 1484, in full_dispatch_request
    rv = self.dispatch_request()
         ^^^^^^^^^^^^^^^^^^^^^^^
  File "C:\projects\hypercon\.venv\Lib\site-packages\flask\app.py", line 1458, in dispatch_request
    self.raise_routing_exception(req)
  File "C:\projects\hypercon\.venv\Lib\site-packages\flask\app.py", line 1440, in raise_routing_exception
    raise request.routing_exception  # type: ignore
    ^^^^^^^^^^^^^^^^^^^^^^^^^^^^^^^
  File "C:\projects\hypercon\.venv\Lib\site-packages\flask\ctx.py", line 353, in match_request
    result = self.url_adapter.match(return_rule=True)  # type: ignore
             ^^^^^^^^^^^^^^^^^^^^^^^^^^^^^^^^^^^^^^^^
  File "C:\projects\hypercon\.venv\Lib\site-packages\werkzeug\routing\map.py", line 629, in match
    raise NotFound() from None
werkzeug.exceptions.NotFound: 404 Not Found: The requested URL was not found on the server. If you entered the URL manually please check your spelling and try again.
2025-07-17 16:48:27,109 ERROR: Exception on /cgi-bin/luci/;stok=/locale [GET] [in C:\projects\hypercon\.venv\Lib\site-packages\flask\app.py:1414]
Traceback (most recent call last):
  File "C:\projects\hypercon\.venv\Lib\site-packages\flask\app.py", line 2190, in wsgi_app
    response = self.full_dispatch_request()
               ^^^^^^^^^^^^^^^^^^^^^^^^^^^^
  File "C:\projects\hypercon\.venv\Lib\site-packages\flask\app.py", line 1486, in full_dispatch_request
    rv = self.handle_user_exception(e)
         ^^^^^^^^^^^^^^^^^^^^^^^^^^^^^
  File "C:\projects\hypercon\.venv\Lib\site-packages\flask\app.py", line 1341, in handle_user_exception
    return self.handle_http_exception(e)
           ^^^^^^^^^^^^^^^^^^^^^^^^^^^^^
  File "C:\projects\hypercon\.venv\Lib\site-packages\flask\app.py", line 1281, in handle_http_exception
    return self.ensure_sync(handler)(e)
           ^^^^^^^^^^^^^^^^^^^^^^^^^^^^
  File "C:\projects\hypercon\.venv\Lib\site-packages\flask\app.py", line 1484, in full_dispatch_request
    rv = self.dispatch_request()
         ^^^^^^^^^^^^^^^^^^^^^^^
  File "C:\projects\hypercon\.venv\Lib\site-packages\flask\app.py", line 1458, in dispatch_request
    self.raise_routing_exception(req)
  File "C:\projects\hypercon\.venv\Lib\site-packages\flask\app.py", line 1440, in raise_routing_exception
    raise request.routing_exception  # type: ignore
    ^^^^^^^^^^^^^^^^^^^^^^^^^^^^^^^
  File "C:\projects\hypercon\.venv\Lib\site-packages\flask\ctx.py", line 353, in match_request
    result = self.url_adapter.match(return_rule=True)  # type: ignore
             ^^^^^^^^^^^^^^^^^^^^^^^^^^^^^^^^^^^^^^^^
  File "C:\projects\hypercon\.venv\Lib\site-packages\werkzeug\routing\map.py", line 629, in match
    raise NotFound() from None
werkzeug.exceptions.NotFound: 404 Not Found: The requested URL was not found on the server. If you entered the URL manually please check your spelling and try again.
2025-07-17 16:48:27,111 ERROR: Unhandled Exception [in C:\projects\hypercon\app\__init__.py:111]
werkzeug.exceptions.InternalServerError: 500 Internal Server Error: The server encountered an internal error and was unable to complete your request. Either the server is overloaded or there is an error in the application.
2025-07-17 16:49:21,154 ERROR: Unhandled Exception [in C:\projects\hypercon\app\__init__.py:111]
Traceback (most recent call last):
  File "C:\projects\hypercon\.venv\Lib\site-packages\flask\app.py", line 1484, in full_dispatch_request
    rv = self.dispatch_request()
         ^^^^^^^^^^^^^^^^^^^^^^^
  File "C:\projects\hypercon\.venv\Lib\site-packages\flask\app.py", line 1458, in dispatch_request
    self.raise_routing_exception(req)
  File "C:\projects\hypercon\.venv\Lib\site-packages\flask\app.py", line 1440, in raise_routing_exception
    raise request.routing_exception  # type: ignore
    ^^^^^^^^^^^^^^^^^^^^^^^^^^^^^^^
  File "C:\projects\hypercon\.venv\Lib\site-packages\flask\ctx.py", line 353, in match_request
    result = self.url_adapter.match(return_rule=True)  # type: ignore
             ^^^^^^^^^^^^^^^^^^^^^^^^^^^^^^^^^^^^^^^^
  File "C:\projects\hypercon\.venv\Lib\site-packages\werkzeug\routing\map.py", line 629, in match
    raise NotFound() from None
werkzeug.exceptions.NotFound: 404 Not Found: The requested URL was not found on the server. If you entered the URL manually please check your spelling and try again.
2025-07-17 16:49:21,155 ERROR: Exception on /cgi-bin/luci/;stok=/locale [GET] [in C:\projects\hypercon\.venv\Lib\site-packages\flask\app.py:1414]
Traceback (most recent call last):
  File "C:\projects\hypercon\.venv\Lib\site-packages\flask\app.py", line 2190, in wsgi_app
    response = self.full_dispatch_request()
               ^^^^^^^^^^^^^^^^^^^^^^^^^^^^
  File "C:\projects\hypercon\.venv\Lib\site-packages\flask\app.py", line 1486, in full_dispatch_request
    rv = self.handle_user_exception(e)
         ^^^^^^^^^^^^^^^^^^^^^^^^^^^^^
  File "C:\projects\hypercon\.venv\Lib\site-packages\flask\app.py", line 1341, in handle_user_exception
    return self.handle_http_exception(e)
           ^^^^^^^^^^^^^^^^^^^^^^^^^^^^^
  File "C:\projects\hypercon\.venv\Lib\site-packages\flask\app.py", line 1281, in handle_http_exception
    return self.ensure_sync(handler)(e)
           ^^^^^^^^^^^^^^^^^^^^^^^^^^^^
  File "C:\projects\hypercon\.venv\Lib\site-packages\flask\app.py", line 1484, in full_dispatch_request
    rv = self.dispatch_request()
         ^^^^^^^^^^^^^^^^^^^^^^^
  File "C:\projects\hypercon\.venv\Lib\site-packages\flask\app.py", line 1458, in dispatch_request
    self.raise_routing_exception(req)
  File "C:\projects\hypercon\.venv\Lib\site-packages\flask\app.py", line 1440, in raise_routing_exception
    raise request.routing_exception  # type: ignore
    ^^^^^^^^^^^^^^^^^^^^^^^^^^^^^^^
  File "C:\projects\hypercon\.venv\Lib\site-packages\flask\ctx.py", line 353, in match_request
    result = self.url_adapter.match(return_rule=True)  # type: ignore
             ^^^^^^^^^^^^^^^^^^^^^^^^^^^^^^^^^^^^^^^^
  File "C:\projects\hypercon\.venv\Lib\site-packages\werkzeug\routing\map.py", line 629, in match
    raise NotFound() from None
werkzeug.exceptions.NotFound: 404 Not Found: The requested URL was not found on the server. If you entered the URL manually please check your spelling and try again.
2025-07-17 16:49:21,157 ERROR: Unhandled Exception [in C:\projects\hypercon\app\__init__.py:111]
werkzeug.exceptions.InternalServerError: 500 Internal Server Error: The server encountered an internal error and was unable to complete your request. Either the server is overloaded or there is an error in the application.
2025-07-17 16:51:08,975 ERROR: Unhandled Exception [in C:\projects\hypercon\app\__init__.py:111]
Traceback (most recent call last):
  File "C:\projects\hypercon\.venv\Lib\site-packages\flask\app.py", line 1484, in full_dispatch_request
    rv = self.dispatch_request()
         ^^^^^^^^^^^^^^^^^^^^^^^
  File "C:\projects\hypercon\.venv\Lib\site-packages\flask\app.py", line 1458, in dispatch_request
    self.raise_routing_exception(req)
  File "C:\projects\hypercon\.venv\Lib\site-packages\flask\app.py", line 1440, in raise_routing_exception
    raise request.routing_exception  # type: ignore
    ^^^^^^^^^^^^^^^^^^^^^^^^^^^^^^^
  File "C:\projects\hypercon\.venv\Lib\site-packages\flask\ctx.py", line 353, in match_request
    result = self.url_adapter.match(return_rule=True)  # type: ignore
             ^^^^^^^^^^^^^^^^^^^^^^^^^^^^^^^^^^^^^^^^
  File "C:\projects\hypercon\.venv\Lib\site-packages\werkzeug\routing\map.py", line 629, in match
    raise NotFound() from None
werkzeug.exceptions.NotFound: 404 Not Found: The requested URL was not found on the server. If you entered the URL manually please check your spelling and try again.
2025-07-17 16:51:08,981 ERROR: Exception on /cgi-bin/luci/;stok=/locale [GET] [in C:\projects\hypercon\.venv\Lib\site-packages\flask\app.py:1414]
Traceback (most recent call last):
  File "C:\projects\hypercon\.venv\Lib\site-packages\flask\app.py", line 2190, in wsgi_app
    response = self.full_dispatch_request()
               ^^^^^^^^^^^^^^^^^^^^^^^^^^^^
  File "C:\projects\hypercon\.venv\Lib\site-packages\flask\app.py", line 1486, in full_dispatch_request
    rv = self.handle_user_exception(e)
         ^^^^^^^^^^^^^^^^^^^^^^^^^^^^^
  File "C:\projects\hypercon\.venv\Lib\site-packages\flask\app.py", line 1341, in handle_user_exception
    return self.handle_http_exception(e)
           ^^^^^^^^^^^^^^^^^^^^^^^^^^^^^
  File "C:\projects\hypercon\.venv\Lib\site-packages\flask\app.py", line 1281, in handle_http_exception
    return self.ensure_sync(handler)(e)
           ^^^^^^^^^^^^^^^^^^^^^^^^^^^^
  File "C:\projects\hypercon\.venv\Lib\site-packages\flask\app.py", line 1484, in full_dispatch_request
    rv = self.dispatch_request()
         ^^^^^^^^^^^^^^^^^^^^^^^
  File "C:\projects\hypercon\.venv\Lib\site-packages\flask\app.py", line 1458, in dispatch_request
    self.raise_routing_exception(req)
  File "C:\projects\hypercon\.venv\Lib\site-packages\flask\app.py", line 1440, in raise_routing_exception
    raise request.routing_exception  # type: ignore
    ^^^^^^^^^^^^^^^^^^^^^^^^^^^^^^^
  File "C:\projects\hypercon\.venv\Lib\site-packages\flask\ctx.py", line 353, in match_request
    result = self.url_adapter.match(return_rule=True)  # type: ignore
             ^^^^^^^^^^^^^^^^^^^^^^^^^^^^^^^^^^^^^^^^
  File "C:\projects\hypercon\.venv\Lib\site-packages\werkzeug\routing\map.py", line 629, in match
    raise NotFound() from None
werkzeug.exceptions.NotFound: 404 Not Found: The requested URL was not found on the server. If you entered the URL manually please check your spelling and try again.
2025-07-17 16:51:08,989 ERROR: Unhandled Exception [in C:\projects\hypercon\app\__init__.py:111]
werkzeug.exceptions.InternalServerError: 500 Internal Server Error: The server encountered an internal error and was unable to complete your request. Either the server is overloaded or there is an error in the application.
2025-07-17 16:52:04,558 ERROR: Unhandled Exception [in C:\projects\hypercon\app\__init__.py:111]
Traceback (most recent call last):
  File "C:\projects\hypercon\.venv\Lib\site-packages\flask\app.py", line 1484, in full_dispatch_request
    rv = self.dispatch_request()
         ^^^^^^^^^^^^^^^^^^^^^^^
  File "C:\projects\hypercon\.venv\Lib\site-packages\flask\app.py", line 1458, in dispatch_request
    self.raise_routing_exception(req)
  File "C:\projects\hypercon\.venv\Lib\site-packages\flask\app.py", line 1440, in raise_routing_exception
    raise request.routing_exception  # type: ignore
    ^^^^^^^^^^^^^^^^^^^^^^^^^^^^^^^
  File "C:\projects\hypercon\.venv\Lib\site-packages\flask\ctx.py", line 353, in match_request
    result = self.url_adapter.match(return_rule=True)  # type: ignore
             ^^^^^^^^^^^^^^^^^^^^^^^^^^^^^^^^^^^^^^^^
  File "C:\projects\hypercon\.venv\Lib\site-packages\werkzeug\routing\map.py", line 629, in match
    raise NotFound() from None
werkzeug.exceptions.NotFound: 404 Not Found: The requested URL was not found on the server. If you entered the URL manually please check your spelling and try again.
2025-07-17 16:52:04,559 ERROR: Exception on /cgi-bin/luci/;stok=/locale [GET] [in C:\projects\hypercon\.venv\Lib\site-packages\flask\app.py:1414]
Traceback (most recent call last):
  File "C:\projects\hypercon\.venv\Lib\site-packages\flask\app.py", line 2190, in wsgi_app
    response = self.full_dispatch_request()
               ^^^^^^^^^^^^^^^^^^^^^^^^^^^^
  File "C:\projects\hypercon\.venv\Lib\site-packages\flask\app.py", line 1486, in full_dispatch_request
    rv = self.handle_user_exception(e)
         ^^^^^^^^^^^^^^^^^^^^^^^^^^^^^
  File "C:\projects\hypercon\.venv\Lib\site-packages\flask\app.py", line 1341, in handle_user_exception
    return self.handle_http_exception(e)
           ^^^^^^^^^^^^^^^^^^^^^^^^^^^^^
  File "C:\projects\hypercon\.venv\Lib\site-packages\flask\app.py", line 1281, in handle_http_exception
    return self.ensure_sync(handler)(e)
           ^^^^^^^^^^^^^^^^^^^^^^^^^^^^
  File "C:\projects\hypercon\.venv\Lib\site-packages\flask\app.py", line 1484, in full_dispatch_request
    rv = self.dispatch_request()
         ^^^^^^^^^^^^^^^^^^^^^^^
  File "C:\projects\hypercon\.venv\Lib\site-packages\flask\app.py", line 1458, in dispatch_request
    self.raise_routing_exception(req)
  File "C:\projects\hypercon\.venv\Lib\site-packages\flask\app.py", line 1440, in raise_routing_exception
    raise request.routing_exception  # type: ignore
    ^^^^^^^^^^^^^^^^^^^^^^^^^^^^^^^
  File "C:\projects\hypercon\.venv\Lib\site-packages\flask\ctx.py", line 353, in match_request
    result = self.url_adapter.match(return_rule=True)  # type: ignore
             ^^^^^^^^^^^^^^^^^^^^^^^^^^^^^^^^^^^^^^^^
  File "C:\projects\hypercon\.venv\Lib\site-packages\werkzeug\routing\map.py", line 629, in match
    raise NotFound() from None
werkzeug.exceptions.NotFound: 404 Not Found: The requested URL was not found on the server. If you entered the URL manually please check your spelling and try again.
2025-07-17 16:52:04,561 ERROR: Unhandled Exception [in C:\projects\hypercon\app\__init__.py:111]
werkzeug.exceptions.InternalServerError: 500 Internal Server Error: The server encountered an internal error and was unable to complete your request. Either the server is overloaded or there is an error in the application.
2025-07-17 16:54:02,850 ERROR: Unhandled Exception [in C:\projects\hypercon\app\__init__.py:111]
Traceback (most recent call last):
  File "C:\projects\hypercon\.venv\Lib\site-packages\flask\app.py", line 1484, in full_dispatch_request
    rv = self.dispatch_request()
         ^^^^^^^^^^^^^^^^^^^^^^^
  File "C:\projects\hypercon\.venv\Lib\site-packages\flask\app.py", line 1458, in dispatch_request
    self.raise_routing_exception(req)
  File "C:\projects\hypercon\.venv\Lib\site-packages\flask\app.py", line 1440, in raise_routing_exception
    raise request.routing_exception  # type: ignore
    ^^^^^^^^^^^^^^^^^^^^^^^^^^^^^^^
  File "C:\projects\hypercon\.venv\Lib\site-packages\flask\ctx.py", line 353, in match_request
    result = self.url_adapter.match(return_rule=True)  # type: ignore
             ^^^^^^^^^^^^^^^^^^^^^^^^^^^^^^^^^^^^^^^^
  File "C:\projects\hypercon\.venv\Lib\site-packages\werkzeug\routing\map.py", line 629, in match
    raise NotFound() from None
werkzeug.exceptions.NotFound: 404 Not Found: The requested URL was not found on the server. If you entered the URL manually please check your spelling and try again.
2025-07-17 16:54:02,854 ERROR: Exception on /cgi-bin/luci/;stok=/locale [GET] [in C:\projects\hypercon\.venv\Lib\site-packages\flask\app.py:1414]
Traceback (most recent call last):
  File "C:\projects\hypercon\.venv\Lib\site-packages\flask\app.py", line 2190, in wsgi_app
    response = self.full_dispatch_request()
               ^^^^^^^^^^^^^^^^^^^^^^^^^^^^
  File "C:\projects\hypercon\.venv\Lib\site-packages\flask\app.py", line 1486, in full_dispatch_request
    rv = self.handle_user_exception(e)
         ^^^^^^^^^^^^^^^^^^^^^^^^^^^^^
  File "C:\projects\hypercon\.venv\Lib\site-packages\flask\app.py", line 1341, in handle_user_exception
    return self.handle_http_exception(e)
           ^^^^^^^^^^^^^^^^^^^^^^^^^^^^^
  File "C:\projects\hypercon\.venv\Lib\site-packages\flask\app.py", line 1281, in handle_http_exception
    return self.ensure_sync(handler)(e)
           ^^^^^^^^^^^^^^^^^^^^^^^^^^^^
  File "C:\projects\hypercon\.venv\Lib\site-packages\flask\app.py", line 1484, in full_dispatch_request
    rv = self.dispatch_request()
         ^^^^^^^^^^^^^^^^^^^^^^^
  File "C:\projects\hypercon\.venv\Lib\site-packages\flask\app.py", line 1458, in dispatch_request
    self.raise_routing_exception(req)
  File "C:\projects\hypercon\.venv\Lib\site-packages\flask\app.py", line 1440, in raise_routing_exception
    raise request.routing_exception  # type: ignore
    ^^^^^^^^^^^^^^^^^^^^^^^^^^^^^^^
  File "C:\projects\hypercon\.venv\Lib\site-packages\flask\ctx.py", line 353, in match_request
    result = self.url_adapter.match(return_rule=True)  # type: ignore
             ^^^^^^^^^^^^^^^^^^^^^^^^^^^^^^^^^^^^^^^^
  File "C:\projects\hypercon\.venv\Lib\site-packages\werkzeug\routing\map.py", line 629, in match
    raise NotFound() from None
werkzeug.exceptions.NotFound: 404 Not Found: The requested URL was not found on the server. If you entered the URL manually please check your spelling and try again.
2025-07-17 16:54:02,861 ERROR: Unhandled Exception [in C:\projects\hypercon\app\__init__.py:111]
werkzeug.exceptions.InternalServerError: 500 Internal Server Error: The server encountered an internal error and was unable to complete your request. Either the server is overloaded or there is an error in the application.
2025-07-17 16:54:51,912 ERROR: Unhandled Exception [in C:\projects\hypercon\app\__init__.py:111]
Traceback (most recent call last):
  File "C:\projects\hypercon\.venv\Lib\site-packages\flask\app.py", line 1484, in full_dispatch_request
    rv = self.dispatch_request()
         ^^^^^^^^^^^^^^^^^^^^^^^
  File "C:\projects\hypercon\.venv\Lib\site-packages\flask\app.py", line 1458, in dispatch_request
    self.raise_routing_exception(req)
  File "C:\projects\hypercon\.venv\Lib\site-packages\flask\app.py", line 1440, in raise_routing_exception
    raise request.routing_exception  # type: ignore
    ^^^^^^^^^^^^^^^^^^^^^^^^^^^^^^^
  File "C:\projects\hypercon\.venv\Lib\site-packages\flask\ctx.py", line 353, in match_request
    result = self.url_adapter.match(return_rule=True)  # type: ignore
             ^^^^^^^^^^^^^^^^^^^^^^^^^^^^^^^^^^^^^^^^
  File "C:\projects\hypercon\.venv\Lib\site-packages\werkzeug\routing\map.py", line 629, in match
    raise NotFound() from None
werkzeug.exceptions.NotFound: 404 Not Found: The requested URL was not found on the server. If you entered the URL manually please check your spelling and try again.
2025-07-17 16:54:51,913 ERROR: Exception on /cgi-bin/luci/;stok=/locale [GET] [in C:\projects\hypercon\.venv\Lib\site-packages\flask\app.py:1414]
Traceback (most recent call last):
  File "C:\projects\hypercon\.venv\Lib\site-packages\flask\app.py", line 2190, in wsgi_app
    response = self.full_dispatch_request()
               ^^^^^^^^^^^^^^^^^^^^^^^^^^^^
  File "C:\projects\hypercon\.venv\Lib\site-packages\flask\app.py", line 1486, in full_dispatch_request
    rv = self.handle_user_exception(e)
         ^^^^^^^^^^^^^^^^^^^^^^^^^^^^^
  File "C:\projects\hypercon\.venv\Lib\site-packages\flask\app.py", line 1341, in handle_user_exception
    return self.handle_http_exception(e)
           ^^^^^^^^^^^^^^^^^^^^^^^^^^^^^
  File "C:\projects\hypercon\.venv\Lib\site-packages\flask\app.py", line 1281, in handle_http_exception
    return self.ensure_sync(handler)(e)
           ^^^^^^^^^^^^^^^^^^^^^^^^^^^^
  File "C:\projects\hypercon\.venv\Lib\site-packages\flask\app.py", line 1484, in full_dispatch_request
    rv = self.dispatch_request()
         ^^^^^^^^^^^^^^^^^^^^^^^
  File "C:\projects\hypercon\.venv\Lib\site-packages\flask\app.py", line 1458, in dispatch_request
    self.raise_routing_exception(req)
  File "C:\projects\hypercon\.venv\Lib\site-packages\flask\app.py", line 1440, in raise_routing_exception
    raise request.routing_exception  # type: ignore
    ^^^^^^^^^^^^^^^^^^^^^^^^^^^^^^^
  File "C:\projects\hypercon\.venv\Lib\site-packages\flask\ctx.py", line 353, in match_request
    result = self.url_adapter.match(return_rule=True)  # type: ignore
             ^^^^^^^^^^^^^^^^^^^^^^^^^^^^^^^^^^^^^^^^
  File "C:\projects\hypercon\.venv\Lib\site-packages\werkzeug\routing\map.py", line 629, in match
    raise NotFound() from None
werkzeug.exceptions.NotFound: 404 Not Found: The requested URL was not found on the server. If you entered the URL manually please check your spelling and try again.
2025-07-17 16:54:51,915 ERROR: Unhandled Exception [in C:\projects\hypercon\app\__init__.py:111]
werkzeug.exceptions.InternalServerError: 500 Internal Server Error: The server encountered an internal error and was unable to complete your request. Either the server is overloaded or there is an error in the application.
2025-07-17 16:57:47,479 ERROR: Unhandled Exception [in C:\projects\hypercon\app\__init__.py:111]
Traceback (most recent call last):
  File "C:\projects\hypercon\.venv\Lib\site-packages\flask\app.py", line 1484, in full_dispatch_request
    rv = self.dispatch_request()
         ^^^^^^^^^^^^^^^^^^^^^^^
  File "C:\projects\hypercon\.venv\Lib\site-packages\flask\app.py", line 1458, in dispatch_request
    self.raise_routing_exception(req)
  File "C:\projects\hypercon\.venv\Lib\site-packages\flask\app.py", line 1440, in raise_routing_exception
    raise request.routing_exception  # type: ignore
    ^^^^^^^^^^^^^^^^^^^^^^^^^^^^^^^
  File "C:\projects\hypercon\.venv\Lib\site-packages\flask\ctx.py", line 353, in match_request
    result = self.url_adapter.match(return_rule=True)  # type: ignore
             ^^^^^^^^^^^^^^^^^^^^^^^^^^^^^^^^^^^^^^^^
  File "C:\projects\hypercon\.venv\Lib\site-packages\werkzeug\routing\map.py", line 629, in match
    raise NotFound() from None
werkzeug.exceptions.NotFound: 404 Not Found: The requested URL was not found on the server. If you entered the URL manually please check your spelling and try again.
2025-07-17 16:57:47,480 ERROR: Exception on /cgi-bin/luci/;stok=/locale [GET] [in C:\projects\hypercon\.venv\Lib\site-packages\flask\app.py:1414]
Traceback (most recent call last):
  File "C:\projects\hypercon\.venv\Lib\site-packages\flask\app.py", line 2190, in wsgi_app
    response = self.full_dispatch_request()
               ^^^^^^^^^^^^^^^^^^^^^^^^^^^^
  File "C:\projects\hypercon\.venv\Lib\site-packages\flask\app.py", line 1486, in full_dispatch_request
    rv = self.handle_user_exception(e)
         ^^^^^^^^^^^^^^^^^^^^^^^^^^^^^
  File "C:\projects\hypercon\.venv\Lib\site-packages\flask\app.py", line 1341, in handle_user_exception
    return self.handle_http_exception(e)
           ^^^^^^^^^^^^^^^^^^^^^^^^^^^^^
  File "C:\projects\hypercon\.venv\Lib\site-packages\flask\app.py", line 1281, in handle_http_exception
    return self.ensure_sync(handler)(e)
           ^^^^^^^^^^^^^^^^^^^^^^^^^^^^
  File "C:\projects\hypercon\.venv\Lib\site-packages\flask\app.py", line 1484, in full_dispatch_request
    rv = self.dispatch_request()
         ^^^^^^^^^^^^^^^^^^^^^^^
  File "C:\projects\hypercon\.venv\Lib\site-packages\flask\app.py", line 1458, in dispatch_request
    self.raise_routing_exception(req)
  File "C:\projects\hypercon\.venv\Lib\site-packages\flask\app.py", line 1440, in raise_routing_exception
    raise request.routing_exception  # type: ignore
    ^^^^^^^^^^^^^^^^^^^^^^^^^^^^^^^
  File "C:\projects\hypercon\.venv\Lib\site-packages\flask\ctx.py", line 353, in match_request
    result = self.url_adapter.match(return_rule=True)  # type: ignore
             ^^^^^^^^^^^^^^^^^^^^^^^^^^^^^^^^^^^^^^^^
  File "C:\projects\hypercon\.venv\Lib\site-packages\werkzeug\routing\map.py", line 629, in match
    raise NotFound() from None
werkzeug.exceptions.NotFound: 404 Not Found: The requested URL was not found on the server. If you entered the URL manually please check your spelling and try again.
2025-07-17 16:57:47,483 ERROR: Unhandled Exception [in C:\projects\hypercon\app\__init__.py:111]
werkzeug.exceptions.InternalServerError: 500 Internal Server Error: The server encountered an internal error and was unable to complete your request. Either the server is overloaded or there is an error in the application.
2025-07-17 16:59:49,845 ERROR: Unhandled Exception [in C:\projects\hypercon\app\__init__.py:111]
Traceback (most recent call last):
  File "C:\projects\hypercon\.venv\Lib\site-packages\flask\app.py", line 1484, in full_dispatch_request
    rv = self.dispatch_request()
         ^^^^^^^^^^^^^^^^^^^^^^^
  File "C:\projects\hypercon\.venv\Lib\site-packages\flask\app.py", line 1458, in dispatch_request
    self.raise_routing_exception(req)
  File "C:\projects\hypercon\.venv\Lib\site-packages\flask\app.py", line 1440, in raise_routing_exception
    raise request.routing_exception  # type: ignore
    ^^^^^^^^^^^^^^^^^^^^^^^^^^^^^^^
  File "C:\projects\hypercon\.venv\Lib\site-packages\flask\ctx.py", line 353, in match_request
    result = self.url_adapter.match(return_rule=True)  # type: ignore
             ^^^^^^^^^^^^^^^^^^^^^^^^^^^^^^^^^^^^^^^^
  File "C:\projects\hypercon\.venv\Lib\site-packages\werkzeug\routing\map.py", line 629, in match
    raise NotFound() from None
werkzeug.exceptions.NotFound: 404 Not Found: The requested URL was not found on the server. If you entered the URL manually please check your spelling and try again.
2025-07-17 16:59:49,850 ERROR: Exception on /cgi-bin/luci/;stok=/locale [GET] [in C:\projects\hypercon\.venv\Lib\site-packages\flask\app.py:1414]
Traceback (most recent call last):
  File "C:\projects\hypercon\.venv\Lib\site-packages\flask\app.py", line 2190, in wsgi_app
    response = self.full_dispatch_request()
               ^^^^^^^^^^^^^^^^^^^^^^^^^^^^
  File "C:\projects\hypercon\.venv\Lib\site-packages\flask\app.py", line 1486, in full_dispatch_request
    rv = self.handle_user_exception(e)
         ^^^^^^^^^^^^^^^^^^^^^^^^^^^^^
  File "C:\projects\hypercon\.venv\Lib\site-packages\flask\app.py", line 1341, in handle_user_exception
    return self.handle_http_exception(e)
           ^^^^^^^^^^^^^^^^^^^^^^^^^^^^^
  File "C:\projects\hypercon\.venv\Lib\site-packages\flask\app.py", line 1281, in handle_http_exception
    return self.ensure_sync(handler)(e)
           ^^^^^^^^^^^^^^^^^^^^^^^^^^^^
  File "C:\projects\hypercon\.venv\Lib\site-packages\flask\app.py", line 1484, in full_dispatch_request
    rv = self.dispatch_request()
         ^^^^^^^^^^^^^^^^^^^^^^^
  File "C:\projects\hypercon\.venv\Lib\site-packages\flask\app.py", line 1458, in dispatch_request
    self.raise_routing_exception(req)
  File "C:\projects\hypercon\.venv\Lib\site-packages\flask\app.py", line 1440, in raise_routing_exception
    raise request.routing_exception  # type: ignore
    ^^^^^^^^^^^^^^^^^^^^^^^^^^^^^^^
  File "C:\projects\hypercon\.venv\Lib\site-packages\flask\ctx.py", line 353, in match_request
    result = self.url_adapter.match(return_rule=True)  # type: ignore
             ^^^^^^^^^^^^^^^^^^^^^^^^^^^^^^^^^^^^^^^^
  File "C:\projects\hypercon\.venv\Lib\site-packages\werkzeug\routing\map.py", line 629, in match
    raise NotFound() from None
werkzeug.exceptions.NotFound: 404 Not Found: The requested URL was not found on the server. If you entered the URL manually please check your spelling and try again.
2025-07-17 16:59:49,858 ERROR: Unhandled Exception [in C:\projects\hypercon\app\__init__.py:111]
werkzeug.exceptions.InternalServerError: 500 Internal Server Error: The server encountered an internal error and was unable to complete your request. Either the server is overloaded or there is an error in the application.
2025-07-17 17:00:33,876 ERROR: Unhandled Exception [in C:\projects\hypercon\app\__init__.py:111]
Traceback (most recent call last):
  File "C:\projects\hypercon\.venv\Lib\site-packages\flask\app.py", line 1484, in full_dispatch_request
    rv = self.dispatch_request()
         ^^^^^^^^^^^^^^^^^^^^^^^
  File "C:\projects\hypercon\.venv\Lib\site-packages\flask\app.py", line 1458, in dispatch_request
    self.raise_routing_exception(req)
  File "C:\projects\hypercon\.venv\Lib\site-packages\flask\app.py", line 1440, in raise_routing_exception
    raise request.routing_exception  # type: ignore
    ^^^^^^^^^^^^^^^^^^^^^^^^^^^^^^^
  File "C:\projects\hypercon\.venv\Lib\site-packages\flask\ctx.py", line 353, in match_request
    result = self.url_adapter.match(return_rule=True)  # type: ignore
             ^^^^^^^^^^^^^^^^^^^^^^^^^^^^^^^^^^^^^^^^
  File "C:\projects\hypercon\.venv\Lib\site-packages\werkzeug\routing\map.py", line 629, in match
    raise NotFound() from None
werkzeug.exceptions.NotFound: 404 Not Found: The requested URL was not found on the server. If you entered the URL manually please check your spelling and try again.
2025-07-17 17:00:33,877 ERROR: Exception on /cgi-bin/luci/;stok=/locale [GET] [in C:\projects\hypercon\.venv\Lib\site-packages\flask\app.py:1414]
Traceback (most recent call last):
  File "C:\projects\hypercon\.venv\Lib\site-packages\flask\app.py", line 2190, in wsgi_app
    response = self.full_dispatch_request()
               ^^^^^^^^^^^^^^^^^^^^^^^^^^^^
  File "C:\projects\hypercon\.venv\Lib\site-packages\flask\app.py", line 1486, in full_dispatch_request
    rv = self.handle_user_exception(e)
         ^^^^^^^^^^^^^^^^^^^^^^^^^^^^^
  File "C:\projects\hypercon\.venv\Lib\site-packages\flask\app.py", line 1341, in handle_user_exception
    return self.handle_http_exception(e)
           ^^^^^^^^^^^^^^^^^^^^^^^^^^^^^
  File "C:\projects\hypercon\.venv\Lib\site-packages\flask\app.py", line 1281, in handle_http_exception
    return self.ensure_sync(handler)(e)
           ^^^^^^^^^^^^^^^^^^^^^^^^^^^^
  File "C:\projects\hypercon\.venv\Lib\site-packages\flask\app.py", line 1484, in full_dispatch_request
    rv = self.dispatch_request()
         ^^^^^^^^^^^^^^^^^^^^^^^
  File "C:\projects\hypercon\.venv\Lib\site-packages\flask\app.py", line 1458, in dispatch_request
    self.raise_routing_exception(req)
  File "C:\projects\hypercon\.venv\Lib\site-packages\flask\app.py", line 1440, in raise_routing_exception
    raise request.routing_exception  # type: ignore
    ^^^^^^^^^^^^^^^^^^^^^^^^^^^^^^^
  File "C:\projects\hypercon\.venv\Lib\site-packages\flask\ctx.py", line 353, in match_request
    result = self.url_adapter.match(return_rule=True)  # type: ignore
             ^^^^^^^^^^^^^^^^^^^^^^^^^^^^^^^^^^^^^^^^
  File "C:\projects\hypercon\.venv\Lib\site-packages\werkzeug\routing\map.py", line 629, in match
    raise NotFound() from None
werkzeug.exceptions.NotFound: 404 Not Found: The requested URL was not found on the server. If you entered the URL manually please check your spelling and try again.
2025-07-17 17:00:33,879 ERROR: Unhandled Exception [in C:\projects\hypercon\app\__init__.py:111]
werkzeug.exceptions.InternalServerError: 500 Internal Server Error: The server encountered an internal error and was unable to complete your request. Either the server is overloaded or there is an error in the application.
2025-07-18 08:47:45,665 INFO: Hypercon startup [in C:\projects\hypercon\app\__init__.py:66]
2025-07-18 08:48:13,578 ERROR: Unhandled Exception [in C:\projects\hypercon\app\__init__.py:111]
Traceback (most recent call last):
  File "C:\projects\hypercon\.venv\Lib\site-packages\flask\app.py", line 1484, in full_dispatch_request
    rv = self.dispatch_request()
         ^^^^^^^^^^^^^^^^^^^^^^^
  File "C:\projects\hypercon\.venv\Lib\site-packages\flask\app.py", line 1458, in dispatch_request
    self.raise_routing_exception(req)
  File "C:\projects\hypercon\.venv\Lib\site-packages\flask\app.py", line 1440, in raise_routing_exception
    raise request.routing_exception  # type: ignore
    ^^^^^^^^^^^^^^^^^^^^^^^^^^^^^^^
  File "C:\projects\hypercon\.venv\Lib\site-packages\flask\ctx.py", line 353, in match_request
    result = self.url_adapter.match(return_rule=True)  # type: ignore
             ^^^^^^^^^^^^^^^^^^^^^^^^^^^^^^^^^^^^^^^^
  File "C:\projects\hypercon\.venv\Lib\site-packages\werkzeug\routing\map.py", line 629, in match
    raise NotFound() from None
werkzeug.exceptions.NotFound: 404 Not Found: The requested URL was not found on the server. If you entered the URL manually please check your spelling and try again.
2025-07-18 08:48:13,588 ERROR: Exception on /favicon.ico [GET] [in C:\projects\hypercon\.venv\Lib\site-packages\flask\app.py:1414]
Traceback (most recent call last):
  File "C:\projects\hypercon\.venv\Lib\site-packages\flask\app.py", line 2190, in wsgi_app
    response = self.full_dispatch_request()
               ^^^^^^^^^^^^^^^^^^^^^^^^^^^^
  File "C:\projects\hypercon\.venv\Lib\site-packages\flask\app.py", line 1486, in full_dispatch_request
    rv = self.handle_user_exception(e)
         ^^^^^^^^^^^^^^^^^^^^^^^^^^^^^
  File "C:\projects\hypercon\.venv\Lib\site-packages\flask\app.py", line 1341, in handle_user_exception
    return self.handle_http_exception(e)
           ^^^^^^^^^^^^^^^^^^^^^^^^^^^^^
  File "C:\projects\hypercon\.venv\Lib\site-packages\flask\app.py", line 1281, in handle_http_exception
    return self.ensure_sync(handler)(e)
           ^^^^^^^^^^^^^^^^^^^^^^^^^^^^
  File "C:\projects\hypercon\.venv\Lib\site-packages\flask\app.py", line 1484, in full_dispatch_request
    rv = self.dispatch_request()
         ^^^^^^^^^^^^^^^^^^^^^^^
  File "C:\projects\hypercon\.venv\Lib\site-packages\flask\app.py", line 1458, in dispatch_request
    self.raise_routing_exception(req)
  File "C:\projects\hypercon\.venv\Lib\site-packages\flask\app.py", line 1440, in raise_routing_exception
    raise request.routing_exception  # type: ignore
    ^^^^^^^^^^^^^^^^^^^^^^^^^^^^^^^
  File "C:\projects\hypercon\.venv\Lib\site-packages\flask\ctx.py", line 353, in match_request
    result = self.url_adapter.match(return_rule=True)  # type: ignore
             ^^^^^^^^^^^^^^^^^^^^^^^^^^^^^^^^^^^^^^^^
  File "C:\projects\hypercon\.venv\Lib\site-packages\werkzeug\routing\map.py", line 629, in match
    raise NotFound() from None
werkzeug.exceptions.NotFound: 404 Not Found: The requested URL was not found on the server. If you entered the URL manually please check your spelling and try again.
2025-07-18 08:48:13,591 ERROR: Unhandled Exception [in C:\projects\hypercon\app\__init__.py:111]
werkzeug.exceptions.InternalServerError: 500 Internal Server Error: The server encountered an internal error and was unable to complete your request. Either the server is overloaded or there is an error in the application.
2025-07-18 08:54:47,159 ERROR: Unhandled Exception [in C:\projects\hypercon\app\__init__.py:111]
Traceback (most recent call last):
  File "C:\projects\hypercon\.venv\Lib\site-packages\flask\app.py", line 1484, in full_dispatch_request
    rv = self.dispatch_request()
         ^^^^^^^^^^^^^^^^^^^^^^^
  File "C:\projects\hypercon\.venv\Lib\site-packages\flask\app.py", line 1458, in dispatch_request
    self.raise_routing_exception(req)
  File "C:\projects\hypercon\.venv\Lib\site-packages\flask\app.py", line 1440, in raise_routing_exception
    raise request.routing_exception  # type: ignore
    ^^^^^^^^^^^^^^^^^^^^^^^^^^^^^^^
  File "C:\projects\hypercon\.venv\Lib\site-packages\flask\ctx.py", line 353, in match_request
    result = self.url_adapter.match(return_rule=True)  # type: ignore
             ^^^^^^^^^^^^^^^^^^^^^^^^^^^^^^^^^^^^^^^^
  File "C:\projects\hypercon\.venv\Lib\site-packages\werkzeug\routing\map.py", line 629, in match
    raise NotFound() from None
werkzeug.exceptions.NotFound: 404 Not Found: The requested URL was not found on the server. If you entered the URL manually please check your spelling and try again.
2025-07-18 08:54:47,164 ERROR: Exception on /console [GET] [in C:\projects\hypercon\.venv\Lib\site-packages\flask\app.py:1414]
Traceback (most recent call last):
  File "C:\projects\hypercon\.venv\Lib\site-packages\flask\app.py", line 2190, in wsgi_app
    response = self.full_dispatch_request()
               ^^^^^^^^^^^^^^^^^^^^^^^^^^^^
  File "C:\projects\hypercon\.venv\Lib\site-packages\flask\app.py", line 1486, in full_dispatch_request
    rv = self.handle_user_exception(e)
         ^^^^^^^^^^^^^^^^^^^^^^^^^^^^^
  File "C:\projects\hypercon\.venv\Lib\site-packages\flask\app.py", line 1341, in handle_user_exception
    return self.handle_http_exception(e)
           ^^^^^^^^^^^^^^^^^^^^^^^^^^^^^
  File "C:\projects\hypercon\.venv\Lib\site-packages\flask\app.py", line 1281, in handle_http_exception
    return self.ensure_sync(handler)(e)
           ^^^^^^^^^^^^^^^^^^^^^^^^^^^^
  File "C:\projects\hypercon\.venv\Lib\site-packages\flask\app.py", line 1484, in full_dispatch_request
    rv = self.dispatch_request()
         ^^^^^^^^^^^^^^^^^^^^^^^
  File "C:\projects\hypercon\.venv\Lib\site-packages\flask\app.py", line 1458, in dispatch_request
    self.raise_routing_exception(req)
  File "C:\projects\hypercon\.venv\Lib\site-packages\flask\app.py", line 1440, in raise_routing_exception
    raise request.routing_exception  # type: ignore
    ^^^^^^^^^^^^^^^^^^^^^^^^^^^^^^^
  File "C:\projects\hypercon\.venv\Lib\site-packages\flask\ctx.py", line 353, in match_request
    result = self.url_adapter.match(return_rule=True)  # type: ignore
             ^^^^^^^^^^^^^^^^^^^^^^^^^^^^^^^^^^^^^^^^
  File "C:\projects\hypercon\.venv\Lib\site-packages\werkzeug\routing\map.py", line 629, in match
    raise NotFound() from None
werkzeug.exceptions.NotFound: 404 Not Found: The requested URL was not found on the server. If you entered the URL manually please check your spelling and try again.
2025-07-18 08:54:47,166 ERROR: Unhandled Exception [in C:\projects\hypercon\app\__init__.py:111]
werkzeug.exceptions.InternalServerError: 500 Internal Server Error: The server encountered an internal error and was unable to complete your request. Either the server is overloaded or there is an error in the application.
2025-07-18 08:56:40,420 ERROR: Unhandled Exception [in C:\projects\hypercon\app\__init__.py:111]
Traceback (most recent call last):
  File "C:\projects\hypercon\.venv\Lib\site-packages\flask\app.py", line 1484, in full_dispatch_request
    rv = self.dispatch_request()
         ^^^^^^^^^^^^^^^^^^^^^^^
  File "C:\projects\hypercon\.venv\Lib\site-packages\flask\app.py", line 1458, in dispatch_request
    self.raise_routing_exception(req)
  File "C:\projects\hypercon\.venv\Lib\site-packages\flask\app.py", line 1440, in raise_routing_exception
    raise request.routing_exception  # type: ignore
    ^^^^^^^^^^^^^^^^^^^^^^^^^^^^^^^
  File "C:\projects\hypercon\.venv\Lib\site-packages\flask\ctx.py", line 353, in match_request
    result = self.url_adapter.match(return_rule=True)  # type: ignore
             ^^^^^^^^^^^^^^^^^^^^^^^^^^^^^^^^^^^^^^^^
  File "C:\projects\hypercon\.venv\Lib\site-packages\werkzeug\routing\map.py", line 629, in match
    raise NotFound() from None
werkzeug.exceptions.NotFound: 404 Not Found: The requested URL was not found on the server. If you entered the URL manually please check your spelling and try again.
2025-07-18 08:56:40,425 ERROR: Exception on /cgi-bin/luci/;stok=/locale [GET] [in C:\projects\hypercon\.venv\Lib\site-packages\flask\app.py:1414]
Traceback (most recent call last):
  File "C:\projects\hypercon\.venv\Lib\site-packages\flask\app.py", line 2190, in wsgi_app
    response = self.full_dispatch_request()
               ^^^^^^^^^^^^^^^^^^^^^^^^^^^^
  File "C:\projects\hypercon\.venv\Lib\site-packages\flask\app.py", line 1486, in full_dispatch_request
    rv = self.handle_user_exception(e)
         ^^^^^^^^^^^^^^^^^^^^^^^^^^^^^
  File "C:\projects\hypercon\.venv\Lib\site-packages\flask\app.py", line 1341, in handle_user_exception
    return self.handle_http_exception(e)
           ^^^^^^^^^^^^^^^^^^^^^^^^^^^^^
  File "C:\projects\hypercon\.venv\Lib\site-packages\flask\app.py", line 1281, in handle_http_exception
    return self.ensure_sync(handler)(e)
           ^^^^^^^^^^^^^^^^^^^^^^^^^^^^
  File "C:\projects\hypercon\.venv\Lib\site-packages\flask\app.py", line 1484, in full_dispatch_request
    rv = self.dispatch_request()
         ^^^^^^^^^^^^^^^^^^^^^^^
  File "C:\projects\hypercon\.venv\Lib\site-packages\flask\app.py", line 1458, in dispatch_request
    self.raise_routing_exception(req)
  File "C:\projects\hypercon\.venv\Lib\site-packages\flask\app.py", line 1440, in raise_routing_exception
    raise request.routing_exception  # type: ignore
    ^^^^^^^^^^^^^^^^^^^^^^^^^^^^^^^
  File "C:\projects\hypercon\.venv\Lib\site-packages\flask\ctx.py", line 353, in match_request
    result = self.url_adapter.match(return_rule=True)  # type: ignore
             ^^^^^^^^^^^^^^^^^^^^^^^^^^^^^^^^^^^^^^^^
  File "C:\projects\hypercon\.venv\Lib\site-packages\werkzeug\routing\map.py", line 629, in match
    raise NotFound() from None
werkzeug.exceptions.NotFound: 404 Not Found: The requested URL was not found on the server. If you entered the URL manually please check your spelling and try again.
2025-07-18 08:56:40,431 ERROR: Unhandled Exception [in C:\projects\hypercon\app\__init__.py:111]
werkzeug.exceptions.InternalServerError: 500 Internal Server Error: The server encountered an internal error and was unable to complete your request. Either the server is overloaded or there is an error in the application.
2025-07-18 08:59:38,787 ERROR: Unhandled Exception [in C:\projects\hypercon\app\__init__.py:111]
Traceback (most recent call last):
  File "C:\projects\hypercon\.venv\Lib\site-packages\flask\app.py", line 1484, in full_dispatch_request
    rv = self.dispatch_request()
         ^^^^^^^^^^^^^^^^^^^^^^^
  File "C:\projects\hypercon\.venv\Lib\site-packages\flask\app.py", line 1458, in dispatch_request
    self.raise_routing_exception(req)
  File "C:\projects\hypercon\.venv\Lib\site-packages\flask\app.py", line 1440, in raise_routing_exception
    raise request.routing_exception  # type: ignore
    ^^^^^^^^^^^^^^^^^^^^^^^^^^^^^^^
  File "C:\projects\hypercon\.venv\Lib\site-packages\flask\ctx.py", line 353, in match_request
    result = self.url_adapter.match(return_rule=True)  # type: ignore
             ^^^^^^^^^^^^^^^^^^^^^^^^^^^^^^^^^^^^^^^^
  File "C:\projects\hypercon\.venv\Lib\site-packages\werkzeug\routing\map.py", line 629, in match
    raise NotFound() from None
werkzeug.exceptions.NotFound: 404 Not Found: The requested URL was not found on the server. If you entered the URL manually please check your spelling and try again.
2025-07-18 08:59:38,788 ERROR: Exception on /cgi-bin/luci/;stok=/locale [GET] [in C:\projects\hypercon\.venv\Lib\site-packages\flask\app.py:1414]
Traceback (most recent call last):
  File "C:\projects\hypercon\.venv\Lib\site-packages\flask\app.py", line 2190, in wsgi_app
    response = self.full_dispatch_request()
               ^^^^^^^^^^^^^^^^^^^^^^^^^^^^
  File "C:\projects\hypercon\.venv\Lib\site-packages\flask\app.py", line 1486, in full_dispatch_request
    rv = self.handle_user_exception(e)
         ^^^^^^^^^^^^^^^^^^^^^^^^^^^^^
  File "C:\projects\hypercon\.venv\Lib\site-packages\flask\app.py", line 1341, in handle_user_exception
    return self.handle_http_exception(e)
           ^^^^^^^^^^^^^^^^^^^^^^^^^^^^^
  File "C:\projects\hypercon\.venv\Lib\site-packages\flask\app.py", line 1281, in handle_http_exception
    return self.ensure_sync(handler)(e)
           ^^^^^^^^^^^^^^^^^^^^^^^^^^^^
  File "C:\projects\hypercon\.venv\Lib\site-packages\flask\app.py", line 1484, in full_dispatch_request
    rv = self.dispatch_request()
         ^^^^^^^^^^^^^^^^^^^^^^^
  File "C:\projects\hypercon\.venv\Lib\site-packages\flask\app.py", line 1458, in dispatch_request
    self.raise_routing_exception(req)
  File "C:\projects\hypercon\.venv\Lib\site-packages\flask\app.py", line 1440, in raise_routing_exception
    raise request.routing_exception  # type: ignore
    ^^^^^^^^^^^^^^^^^^^^^^^^^^^^^^^
  File "C:\projects\hypercon\.venv\Lib\site-packages\flask\ctx.py", line 353, in match_request
    result = self.url_adapter.match(return_rule=True)  # type: ignore
             ^^^^^^^^^^^^^^^^^^^^^^^^^^^^^^^^^^^^^^^^
  File "C:\projects\hypercon\.venv\Lib\site-packages\werkzeug\routing\map.py", line 629, in match
    raise NotFound() from None
werkzeug.exceptions.NotFound: 404 Not Found: The requested URL was not found on the server. If you entered the URL manually please check your spelling and try again.
2025-07-18 08:59:38,790 ERROR: Unhandled Exception [in C:\projects\hypercon\app\__init__.py:111]
werkzeug.exceptions.InternalServerError: 500 Internal Server Error: The server encountered an internal error and was unable to complete your request. Either the server is overloaded or there is an error in the application.
2025-07-18 09:08:38,129 INFO: Hypercon startup [in C:\projects\hypercon\app\__init__.py:66]
2025-07-18 09:11:45,689 INFO: Hypercon startup [in C:\projects\hypercon\app\__init__.py:67]
2025-07-18 09:11:48,911 ERROR: Unhandled Exception [in C:\projects\hypercon\app\__init__.py:112]
Traceback (most recent call last):
  File "C:\projects\hypercon\.venv\Lib\site-packages\flask\app.py", line 1484, in full_dispatch_request
    rv = self.dispatch_request()
         ^^^^^^^^^^^^^^^^^^^^^^^
  File "C:\projects\hypercon\.venv\Lib\site-packages\flask\app.py", line 1469, in dispatch_request
    return self.ensure_sync(self.view_functions[rule.endpoint])(**view_args)
           ^^^^^^^^^^^^^^^^^^^^^^^^^^^^^^^^^^^^^^^^^^^^^^^^^^^^^^^^^^^^^^^^^
  File "C:\projects\hypercon\app\__init__.py", line 137, in favicon
    return send_from_directory(os.path.join(app.root_path, 'static'), 'favicon.ico',
           ^^^^^^^^^^^^^^^^^^^^^^^^^^^^^^^^^^^^^^^^^^^^^^^^^^^^^^^^^^^^^^^^^^^^^^^^^
  File "C:\projects\hypercon\.venv\Lib\site-packages\flask\helpers.py", line 557, in send_from_directory
    return werkzeug.utils.send_from_directory(  # type: ignore[return-value]
           ^^^^^^^^^^^^^^^^^^^^^^^^^^^^^^^^^^^^^^^^^^^^^^^^^^^^^^^^^^^^^^^^^
  File "C:\projects\hypercon\.venv\Lib\site-packages\werkzeug\utils.py", line 575, in send_from_directory
    raise NotFound()
werkzeug.exceptions.NotFound: 404 Not Found: The requested URL was not found on the server. If you entered the URL manually please check your spelling and try again.
2025-07-18 09:11:48,927 ERROR: Exception on /favicon.ico [GET] [in C:\projects\hypercon\.venv\Lib\site-packages\flask\app.py:1414]
Traceback (most recent call last):
  File "C:\projects\hypercon\.venv\Lib\site-packages\flask\app.py", line 2190, in wsgi_app
    response = self.full_dispatch_request()
               ^^^^^^^^^^^^^^^^^^^^^^^^^^^^
  File "C:\projects\hypercon\.venv\Lib\site-packages\flask\app.py", line 1486, in full_dispatch_request
    rv = self.handle_user_exception(e)
         ^^^^^^^^^^^^^^^^^^^^^^^^^^^^^
  File "C:\projects\hypercon\.venv\Lib\site-packages\flask\app.py", line 1341, in handle_user_exception
    return self.handle_http_exception(e)
           ^^^^^^^^^^^^^^^^^^^^^^^^^^^^^
  File "C:\projects\hypercon\.venv\Lib\site-packages\flask\app.py", line 1281, in handle_http_exception
    return self.ensure_sync(handler)(e)
           ^^^^^^^^^^^^^^^^^^^^^^^^^^^^
  File "C:\projects\hypercon\.venv\Lib\site-packages\flask\app.py", line 1484, in full_dispatch_request
    rv = self.dispatch_request()
         ^^^^^^^^^^^^^^^^^^^^^^^
  File "C:\projects\hypercon\.venv\Lib\site-packages\flask\app.py", line 1469, in dispatch_request
    return self.ensure_sync(self.view_functions[rule.endpoint])(**view_args)
           ^^^^^^^^^^^^^^^^^^^^^^^^^^^^^^^^^^^^^^^^^^^^^^^^^^^^^^^^^^^^^^^^^
  File "C:\projects\hypercon\app\__init__.py", line 137, in favicon
    return send_from_directory(os.path.join(app.root_path, 'static'), 'favicon.ico',
           ^^^^^^^^^^^^^^^^^^^^^^^^^^^^^^^^^^^^^^^^^^^^^^^^^^^^^^^^^^^^^^^^^^^^^^^^^
  File "C:\projects\hypercon\.venv\Lib\site-packages\flask\helpers.py", line 557, in send_from_directory
    return werkzeug.utils.send_from_directory(  # type: ignore[return-value]
           ^^^^^^^^^^^^^^^^^^^^^^^^^^^^^^^^^^^^^^^^^^^^^^^^^^^^^^^^^^^^^^^^^
  File "C:\projects\hypercon\.venv\Lib\site-packages\werkzeug\utils.py", line 575, in send_from_directory
    raise NotFound()
werkzeug.exceptions.NotFound: 404 Not Found: The requested URL was not found on the server. If you entered the URL manually please check your spelling and try again.
2025-07-18 09:11:48,929 ERROR: Unhandled Exception [in C:\projects\hypercon\app\__init__.py:112]
werkzeug.exceptions.InternalServerError: 500 Internal Server Error: The server encountered an internal error and was unable to complete your request. Either the server is overloaded or there is an error in the application.
2025-07-18 09:12:51,091 INFO: Hypercon startup [in C:\projects\hypercon\app\__init__.py:67]
2025-07-18 09:12:52,683 ERROR: Unhandled Exception [in C:\projects\hypercon\app\__init__.py:112]
Traceback (most recent call last):
  File "C:\projects\hypercon\.venv\Lib\site-packages\flask\app.py", line 1484, in full_dispatch_request
    rv = self.dispatch_request()
         ^^^^^^^^^^^^^^^^^^^^^^^
  File "C:\projects\hypercon\.venv\Lib\site-packages\flask\app.py", line 1469, in dispatch_request
    return self.ensure_sync(self.view_functions[rule.endpoint])(**view_args)
           ^^^^^^^^^^^^^^^^^^^^^^^^^^^^^^^^^^^^^^^^^^^^^^^^^^^^^^^^^^^^^^^^^
  File "C:\projects\hypercon\app\__init__.py", line 137, in favicon
    return send_from_directory(os.path.join(app.root_path, 'static'), 'favicon.ico',
           ^^^^^^^^^^^^^^^^^^^^^^^^^^^^^^^^^^^^^^^^^^^^^^^^^^^^^^^^^^^^^^^^^^^^^^^^^
  File "C:\projects\hypercon\.venv\Lib\site-packages\flask\helpers.py", line 557, in send_from_directory
    return werkzeug.utils.send_from_directory(  # type: ignore[return-value]
           ^^^^^^^^^^^^^^^^^^^^^^^^^^^^^^^^^^^^^^^^^^^^^^^^^^^^^^^^^^^^^^^^^
  File "C:\projects\hypercon\.venv\Lib\site-packages\werkzeug\utils.py", line 575, in send_from_directory
    raise NotFound()
werkzeug.exceptions.NotFound: 404 Not Found: The requested URL was not found on the server. If you entered the URL manually please check your spelling and try again.
2025-07-18 09:12:52,689 ERROR: Exception on /favicon.ico [GET] [in C:\projects\hypercon\.venv\Lib\site-packages\flask\app.py:1414]
Traceback (most recent call last):
  File "C:\projects\hypercon\.venv\Lib\site-packages\flask\app.py", line 2190, in wsgi_app
    response = self.full_dispatch_request()
               ^^^^^^^^^^^^^^^^^^^^^^^^^^^^
  File "C:\projects\hypercon\.venv\Lib\site-packages\flask\app.py", line 1486, in full_dispatch_request
    rv = self.handle_user_exception(e)
         ^^^^^^^^^^^^^^^^^^^^^^^^^^^^^
  File "C:\projects\hypercon\.venv\Lib\site-packages\flask\app.py", line 1341, in handle_user_exception
    return self.handle_http_exception(e)
           ^^^^^^^^^^^^^^^^^^^^^^^^^^^^^
  File "C:\projects\hypercon\.venv\Lib\site-packages\flask\app.py", line 1281, in handle_http_exception
    return self.ensure_sync(handler)(e)
           ^^^^^^^^^^^^^^^^^^^^^^^^^^^^
  File "C:\projects\hypercon\.venv\Lib\site-packages\flask\app.py", line 1484, in full_dispatch_request
    rv = self.dispatch_request()
         ^^^^^^^^^^^^^^^^^^^^^^^
  File "C:\projects\hypercon\.venv\Lib\site-packages\flask\app.py", line 1469, in dispatch_request
    return self.ensure_sync(self.view_functions[rule.endpoint])(**view_args)
           ^^^^^^^^^^^^^^^^^^^^^^^^^^^^^^^^^^^^^^^^^^^^^^^^^^^^^^^^^^^^^^^^^
  File "C:\projects\hypercon\app\__init__.py", line 137, in favicon
    return send_from_directory(os.path.join(app.root_path, 'static'), 'favicon.ico',
           ^^^^^^^^^^^^^^^^^^^^^^^^^^^^^^^^^^^^^^^^^^^^^^^^^^^^^^^^^^^^^^^^^^^^^^^^^
  File "C:\projects\hypercon\.venv\Lib\site-packages\flask\helpers.py", line 557, in send_from_directory
    return werkzeug.utils.send_from_directory(  # type: ignore[return-value]
           ^^^^^^^^^^^^^^^^^^^^^^^^^^^^^^^^^^^^^^^^^^^^^^^^^^^^^^^^^^^^^^^^^
  File "C:\projects\hypercon\.venv\Lib\site-packages\werkzeug\utils.py", line 575, in send_from_directory
    raise NotFound()
werkzeug.exceptions.NotFound: 404 Not Found: The requested URL was not found on the server. If you entered the URL manually please check your spelling and try again.
2025-07-18 09:12:52,691 ERROR: Unhandled Exception [in C:\projects\hypercon\app\__init__.py:112]
werkzeug.exceptions.InternalServerError: 500 Internal Server Error: The server encountered an internal error and was unable to complete your request. Either the server is overloaded or there is an error in the application.
2025-07-18 09:15:23,857 INFO: Hypercon startup [in C:\projects\hypercon\app\__init__.py:67]
2025-07-18 09:20:06,917 ERROR: Unhandled Exception [in C:\projects\hypercon\app\__init__.py:112]
Traceback (most recent call last):
  File "C:\projects\hypercon\.venv\Lib\site-packages\flask\app.py", line 1484, in full_dispatch_request
    rv = self.dispatch_request()
         ^^^^^^^^^^^^^^^^^^^^^^^
  File "C:\projects\hypercon\.venv\Lib\site-packages\flask\app.py", line 1458, in dispatch_request
    self.raise_routing_exception(req)
  File "C:\projects\hypercon\.venv\Lib\site-packages\flask\app.py", line 1440, in raise_routing_exception
    raise request.routing_exception  # type: ignore
    ^^^^^^^^^^^^^^^^^^^^^^^^^^^^^^^
  File "C:\projects\hypercon\.venv\Lib\site-packages\flask\ctx.py", line 353, in match_request
    result = self.url_adapter.match(return_rule=True)  # type: ignore
             ^^^^^^^^^^^^^^^^^^^^^^^^^^^^^^^^^^^^^^^^
  File "C:\projects\hypercon\.venv\Lib\site-packages\werkzeug\routing\map.py", line 629, in match
    raise NotFound() from None
werkzeug.exceptions.NotFound: 404 Not Found: The requested URL was not found on the server. If you entered the URL manually please check your spelling and try again.
2025-07-18 09:20:06,923 ERROR: Exception on /cgi-bin/luci/;stok=/locale [GET] [in C:\projects\hypercon\.venv\Lib\site-packages\flask\app.py:1414]
Traceback (most recent call last):
  File "C:\projects\hypercon\.venv\Lib\site-packages\flask\app.py", line 2190, in wsgi_app
    response = self.full_dispatch_request()
               ^^^^^^^^^^^^^^^^^^^^^^^^^^^^
  File "C:\projects\hypercon\.venv\Lib\site-packages\flask\app.py", line 1486, in full_dispatch_request
    rv = self.handle_user_exception(e)
         ^^^^^^^^^^^^^^^^^^^^^^^^^^^^^
  File "C:\projects\hypercon\.venv\Lib\site-packages\flask\app.py", line 1341, in handle_user_exception
    return self.handle_http_exception(e)
           ^^^^^^^^^^^^^^^^^^^^^^^^^^^^^
  File "C:\projects\hypercon\.venv\Lib\site-packages\flask\app.py", line 1281, in handle_http_exception
    return self.ensure_sync(handler)(e)
           ^^^^^^^^^^^^^^^^^^^^^^^^^^^^
  File "C:\projects\hypercon\.venv\Lib\site-packages\flask\app.py", line 1484, in full_dispatch_request
    rv = self.dispatch_request()
         ^^^^^^^^^^^^^^^^^^^^^^^
  File "C:\projects\hypercon\.venv\Lib\site-packages\flask\app.py", line 1458, in dispatch_request
    self.raise_routing_exception(req)
  File "C:\projects\hypercon\.venv\Lib\site-packages\flask\app.py", line 1440, in raise_routing_exception
    raise request.routing_exception  # type: ignore
    ^^^^^^^^^^^^^^^^^^^^^^^^^^^^^^^
  File "C:\projects\hypercon\.venv\Lib\site-packages\flask\ctx.py", line 353, in match_request
    result = self.url_adapter.match(return_rule=True)  # type: ignore
             ^^^^^^^^^^^^^^^^^^^^^^^^^^^^^^^^^^^^^^^^
  File "C:\projects\hypercon\.venv\Lib\site-packages\werkzeug\routing\map.py", line 629, in match
    raise NotFound() from None
werkzeug.exceptions.NotFound: 404 Not Found: The requested URL was not found on the server. If you entered the URL manually please check your spelling and try again.
2025-07-18 09:20:06,924 ERROR: Unhandled Exception [in C:\projects\hypercon\app\__init__.py:112]
werkzeug.exceptions.InternalServerError: 500 Internal Server Error: The server encountered an internal error and was unable to complete your request. Either the server is overloaded or there is an error in the application.
2025-07-18 09:22:57,470 ERROR: Unhandled Exception [in C:\projects\hypercon\app\__init__.py:112]
Traceback (most recent call last):
  File "C:\projects\hypercon\.venv\Lib\site-packages\flask\app.py", line 1484, in full_dispatch_request
    rv = self.dispatch_request()
         ^^^^^^^^^^^^^^^^^^^^^^^
  File "C:\projects\hypercon\.venv\Lib\site-packages\flask\app.py", line 1458, in dispatch_request
    self.raise_routing_exception(req)
  File "C:\projects\hypercon\.venv\Lib\site-packages\flask\app.py", line 1440, in raise_routing_exception
    raise request.routing_exception  # type: ignore
    ^^^^^^^^^^^^^^^^^^^^^^^^^^^^^^^
  File "C:\projects\hypercon\.venv\Lib\site-packages\flask\ctx.py", line 353, in match_request
    result = self.url_adapter.match(return_rule=True)  # type: ignore
             ^^^^^^^^^^^^^^^^^^^^^^^^^^^^^^^^^^^^^^^^
  File "C:\projects\hypercon\.venv\Lib\site-packages\werkzeug\routing\map.py", line 629, in match
    raise NotFound() from None
werkzeug.exceptions.NotFound: 404 Not Found: The requested URL was not found on the server. If you entered the URL manually please check your spelling and try again.
2025-07-18 09:22:57,471 ERROR: Exception on /cgi-bin/luci/;stok=/locale [GET] [in C:\projects\hypercon\.venv\Lib\site-packages\flask\app.py:1414]
Traceback (most recent call last):
  File "C:\projects\hypercon\.venv\Lib\site-packages\flask\app.py", line 2190, in wsgi_app
    response = self.full_dispatch_request()
               ^^^^^^^^^^^^^^^^^^^^^^^^^^^^
  File "C:\projects\hypercon\.venv\Lib\site-packages\flask\app.py", line 1486, in full_dispatch_request
    rv = self.handle_user_exception(e)
         ^^^^^^^^^^^^^^^^^^^^^^^^^^^^^
  File "C:\projects\hypercon\.venv\Lib\site-packages\flask\app.py", line 1341, in handle_user_exception
    return self.handle_http_exception(e)
           ^^^^^^^^^^^^^^^^^^^^^^^^^^^^^
  File "C:\projects\hypercon\.venv\Lib\site-packages\flask\app.py", line 1281, in handle_http_exception
    return self.ensure_sync(handler)(e)
           ^^^^^^^^^^^^^^^^^^^^^^^^^^^^
  File "C:\projects\hypercon\.venv\Lib\site-packages\flask\app.py", line 1484, in full_dispatch_request
    rv = self.dispatch_request()
         ^^^^^^^^^^^^^^^^^^^^^^^
  File "C:\projects\hypercon\.venv\Lib\site-packages\flask\app.py", line 1458, in dispatch_request
    self.raise_routing_exception(req)
  File "C:\projects\hypercon\.venv\Lib\site-packages\flask\app.py", line 1440, in raise_routing_exception
    raise request.routing_exception  # type: ignore
    ^^^^^^^^^^^^^^^^^^^^^^^^^^^^^^^
  File "C:\projects\hypercon\.venv\Lib\site-packages\flask\ctx.py", line 353, in match_request
    result = self.url_adapter.match(return_rule=True)  # type: ignore
             ^^^^^^^^^^^^^^^^^^^^^^^^^^^^^^^^^^^^^^^^
  File "C:\projects\hypercon\.venv\Lib\site-packages\werkzeug\routing\map.py", line 629, in match
    raise NotFound() from None
werkzeug.exceptions.NotFound: 404 Not Found: The requested URL was not found on the server. If you entered the URL manually please check your spelling and try again.
2025-07-18 09:22:57,473 ERROR: Unhandled Exception [in C:\projects\hypercon\app\__init__.py:112]
werkzeug.exceptions.InternalServerError: 500 Internal Server Error: The server encountered an internal error and was unable to complete your request. Either the server is overloaded or there is an error in the application.
2025-07-18 09:23:21,367 INFO: Hypercon startup [in C:\projects\hypercon\app\__init__.py:67]
2025-07-18 09:46:15,069 INFO: Hypercon startup [in C:\projects\hypercon\app\__init__.py:67]
2025-07-18 10:19:08,450 ERROR: Unhandled Exception [in C:\projects\hypercon\app\__init__.py:112]
Traceback (most recent call last):
  File "C:\projects\hypercon\venv\Lib\site-packages\flask\app.py", line 1484, in full_dispatch_request
    rv = self.dispatch_request()
         ^^^^^^^^^^^^^^^^^^^^^^^
  File "C:\projects\hypercon\venv\Lib\site-packages\flask\app.py", line 1458, in dispatch_request
    self.raise_routing_exception(req)
  File "C:\projects\hypercon\venv\Lib\site-packages\flask\app.py", line 1440, in raise_routing_exception
    raise request.routing_exception  # type: ignore
    ^^^^^^^^^^^^^^^^^^^^^^^^^^^^^^^
  File "C:\projects\hypercon\venv\Lib\site-packages\flask\ctx.py", line 353, in match_request
    result = self.url_adapter.match(return_rule=True)  # type: ignore
             ^^^^^^^^^^^^^^^^^^^^^^^^^^^^^^^^^^^^^^^^
  File "C:\projects\hypercon\venv\Lib\site-packages\werkzeug\routing\map.py", line 629, in match
    raise NotFound() from None
werkzeug.exceptions.NotFound: 404 Not Found: The requested URL was not found on the server. If you entered the URL manually please check your spelling and try again.
2025-07-18 10:19:08,453 ERROR: Exception on /cgi-bin/luci/;stok=/locale [GET] [in C:\projects\hypercon\venv\Lib\site-packages\flask\app.py:1414]
Traceback (most recent call last):
  File "C:\projects\hypercon\venv\Lib\site-packages\flask\app.py", line 2190, in wsgi_app
    response = self.full_dispatch_request()
               ^^^^^^^^^^^^^^^^^^^^^^^^^^^^
  File "C:\projects\hypercon\venv\Lib\site-packages\flask\app.py", line 1486, in full_dispatch_request
    rv = self.handle_user_exception(e)
         ^^^^^^^^^^^^^^^^^^^^^^^^^^^^^
  File "C:\projects\hypercon\venv\Lib\site-packages\flask\app.py", line 1341, in handle_user_exception
    return self.handle_http_exception(e)
           ^^^^^^^^^^^^^^^^^^^^^^^^^^^^^
  File "C:\projects\hypercon\venv\Lib\site-packages\flask\app.py", line 1281, in handle_http_exception
    return self.ensure_sync(handler)(e)
           ^^^^^^^^^^^^^^^^^^^^^^^^^^^^
  File "C:\projects\hypercon\venv\Lib\site-packages\flask\app.py", line 1484, in full_dispatch_request
    rv = self.dispatch_request()
         ^^^^^^^^^^^^^^^^^^^^^^^
  File "C:\projects\hypercon\venv\Lib\site-packages\flask\app.py", line 1458, in dispatch_request
    self.raise_routing_exception(req)
  File "C:\projects\hypercon\venv\Lib\site-packages\flask\app.py", line 1440, in raise_routing_exception
    raise request.routing_exception  # type: ignore
    ^^^^^^^^^^^^^^^^^^^^^^^^^^^^^^^
  File "C:\projects\hypercon\venv\Lib\site-packages\flask\ctx.py", line 353, in match_request
    result = self.url_adapter.match(return_rule=True)  # type: ignore
             ^^^^^^^^^^^^^^^^^^^^^^^^^^^^^^^^^^^^^^^^
  File "C:\projects\hypercon\venv\Lib\site-packages\werkzeug\routing\map.py", line 629, in match
    raise NotFound() from None
werkzeug.exceptions.NotFound: 404 Not Found: The requested URL was not found on the server. If you entered the URL manually please check your spelling and try again.
2025-07-18 10:19:08,453 ERROR: Unhandled Exception [in C:\projects\hypercon\app\__init__.py:112]
werkzeug.exceptions.InternalServerError: 500 Internal Server Error: The server encountered an internal error and was unable to complete your request. Either the server is overloaded or there is an error in the application.
